{
 "cells": [
  {
   "cell_type": "code",
   "execution_count": 1,
   "metadata": {},
   "outputs": [
    {
     "name": "stdout",
     "output_type": "stream",
     "text": [
      "WARNING:tensorflow:From C:\\Users\\DELL\\AppData\\Roaming\\Python\\Python39\\site-packages\\keras\\src\\losses.py:2976: The name tf.losses.sparse_softmax_cross_entropy is deprecated. Please use tf.compat.v1.losses.sparse_softmax_cross_entropy instead.\n",
      "\n"
     ]
    }
   ],
   "source": [
    "\n",
    "import cv2\n",
    "\n",
    "import numpy as np\n",
    "from tensorflow.keras.models import load_model\n",
    "from mongoengine import connect, Document, StringField"
   ]
  },
  {
   "cell_type": "code",
   "execution_count": 2,
   "metadata": {},
   "outputs": [],
   "source": [
    "emotion_dict = {0: 'Angry', 1: 'Disgust', 2: 'Fear', 3: 'Happy', 4: 'Neutral', 5: 'Sad', 6: 'Surprise'}"
   ]
  },
  {
   "cell_type": "code",
   "execution_count": 3,
   "metadata": {},
   "outputs": [
    {
     "name": "stdout",
     "output_type": "stream",
     "text": [
      "WARNING:tensorflow:From C:\\Users\\DELL\\AppData\\Roaming\\Python\\Python39\\site-packages\\keras\\src\\backend.py:1398: The name tf.executing_eagerly_outside_functions is deprecated. Please use tf.compat.v1.executing_eagerly_outside_functions instead.\n",
      "\n",
      "WARNING:tensorflow:From C:\\Users\\DELL\\AppData\\Roaming\\Python\\Python39\\site-packages\\keras\\src\\layers\\normalization\\batch_normalization.py:979: The name tf.nn.fused_batch_norm is deprecated. Please use tf.compat.v1.nn.fused_batch_norm instead.\n",
      "\n"
     ]
    }
   ],
   "source": [
    "emotion_model = load_model('modelFinalPfa.h5')"
   ]
  },
  {
   "cell_type": "code",
   "execution_count": 8,
   "metadata": {},
   "outputs": [
    {
     "data": {
      "text/plain": [
       "<keras.src.engine.functional.Functional at 0x1971d331a00>"
      ]
     },
     "execution_count": 8,
     "metadata": {},
     "output_type": "execute_result"
    }
   ],
   "source": [
    "emotion_model.predict()"
   ]
  },
  {
   "cell_type": "code",
   "execution_count": 4,
   "metadata": {},
   "outputs": [],
   "source": [
    "face_detector = cv2.CascadeClassifier(cv2.data.haarcascades + 'haarcascade_frontalface_default.xml')"
   ]
  },
  {
   "cell_type": "code",
   "execution_count": 5,
   "metadata": {},
   "outputs": [],
   "source": [
    "def process_video(input_video_path):\n",
    "    cap = cv2.VideoCapture(input_video_path)\n",
    "    if not cap.isOpened():\n",
    "        print(\"nonono\")\n",
    "        return None\n",
    "\n",
    "    emotion_counts = {emotion: 0 for emotion in emotion_dict.values()}\n",
    "    total_frames = 0\n",
    "\n",
    "    while True:\n",
    "        ret, frame = cap.read()\n",
    "        if not ret:\n",
    "            break\n",
    "\n",
    "        total_frames += 1\n",
    "        gray_frame = cv2.cvtColor(frame, cv2.COLOR_BGR2GRAY)\n",
    "        faces = face_detector.detectMultiScale(gray_frame, scaleFactor=1.3, minNeighbors=10)\n",
    "\n",
    "        for (x, y, w, h) in faces:\n",
    "            roi_gray_frame = gray_frame[y:y+h, x:x+w]\n",
    "            gray_input = cv2.resize(roi_gray_frame, (48, 48))\n",
    "            rgb_input = cv2.cvtColor(gray_input, cv2.COLOR_GRAY2RGB)  # Convert to 3 channels (RGB)\n",
    "            rgb_input = np.expand_dims(rgb_input, axis=0)\n",
    "            rgb_input = rgb_input / 255.0\n",
    "\n",
    "            try:\n",
    "                print(\"ani wkeft\")\n",
    "                emotion_prediction = emotion_model.predict(rgb_input)\n",
    "                print(\"waywa taadit\")\n",
    "                maxindex = int(np.argmax(emotion_prediction))\n",
    "                emotion_counts[emotion_dict[maxindex]] += 1\n",
    "            except Exception as e:\n",
    "                print(f\"Error during prediction: {e}\")\n",
    "\n",
    "    cap.release()\n",
    "    if total_frames == 0:\n",
    "        return None\n",
    "    emotion_percentages = {emotion: (count / total_frames) * 100 for emotion, count in emotion_counts.items()}\n",
    "    return emotion_percentages"
   ]
  },
  {
   "cell_type": "code",
   "execution_count": 7,
   "metadata": {},
   "outputs": [
    {
     "name": "stdout",
     "output_type": "stream",
     "text": [
      "ani wkeft\n",
      "Error during prediction: in user code:\n",
      "\n",
      "    File \"C:\\Users\\DELL\\AppData\\Roaming\\Python\\Python39\\site-packages\\keras\\src\\engine\\training.py\", line 2440, in predict_function  *\n",
      "        return step_function(self, iterator)\n",
      "    File \"C:\\Users\\DELL\\AppData\\Roaming\\Python\\Python39\\site-packages\\keras\\src\\engine\\training.py\", line 2425, in step_function  **\n",
      "        outputs = model.distribute_strategy.run(run_step, args=(data,))\n",
      "    File \"C:\\Users\\DELL\\AppData\\Roaming\\Python\\Python39\\site-packages\\keras\\src\\engine\\training.py\", line 2413, in run_step  **\n",
      "        outputs = model.predict_step(data)\n",
      "    File \"C:\\Users\\DELL\\AppData\\Roaming\\Python\\Python39\\site-packages\\keras\\src\\engine\\training.py\", line 2381, in predict_step\n",
      "        return self(x, training=False)\n",
      "    File \"C:\\Users\\DELL\\AppData\\Roaming\\Python\\Python39\\site-packages\\keras\\src\\utils\\traceback_utils.py\", line 70, in error_handler\n",
      "        raise e.with_traceback(filtered_tb) from None\n",
      "    File \"C:\\Users\\DELL\\AppData\\Roaming\\Python\\Python39\\site-packages\\keras\\src\\engine\\input_spec.py\", line 219, in assert_input_compatibility\n",
      "        raise ValueError(\n",
      "\n",
      "    ValueError: Layer \"model_2\" expects 2 input(s), but it received 1 input tensors. Inputs received: [<tf.Tensor 'IteratorGetNext:0' shape=(None, 48, 48, 3) dtype=float32>]\n",
      "\n",
      "ani wkeft\n",
      "Error during prediction: in user code:\n",
      "\n",
      "    File \"C:\\Users\\DELL\\AppData\\Roaming\\Python\\Python39\\site-packages\\keras\\src\\engine\\training.py\", line 2440, in predict_function  *\n",
      "        return step_function(self, iterator)\n",
      "    File \"C:\\Users\\DELL\\AppData\\Roaming\\Python\\Python39\\site-packages\\keras\\src\\engine\\training.py\", line 2425, in step_function  **\n",
      "        outputs = model.distribute_strategy.run(run_step, args=(data,))\n",
      "    File \"C:\\Users\\DELL\\AppData\\Roaming\\Python\\Python39\\site-packages\\keras\\src\\engine\\training.py\", line 2413, in run_step  **\n",
      "        outputs = model.predict_step(data)\n",
      "    File \"C:\\Users\\DELL\\AppData\\Roaming\\Python\\Python39\\site-packages\\keras\\src\\engine\\training.py\", line 2381, in predict_step\n",
      "        return self(x, training=False)\n",
      "    File \"C:\\Users\\DELL\\AppData\\Roaming\\Python\\Python39\\site-packages\\keras\\src\\utils\\traceback_utils.py\", line 70, in error_handler\n",
      "        raise e.with_traceback(filtered_tb) from None\n",
      "    File \"C:\\Users\\DELL\\AppData\\Roaming\\Python\\Python39\\site-packages\\keras\\src\\engine\\input_spec.py\", line 219, in assert_input_compatibility\n",
      "        raise ValueError(\n",
      "\n",
      "    ValueError: Layer \"model_2\" expects 2 input(s), but it received 1 input tensors. Inputs received: [<tf.Tensor 'IteratorGetNext:0' shape=(None, 48, 48, 3) dtype=float32>]\n",
      "\n",
      "ani wkeft\n",
      "Error during prediction: in user code:\n",
      "\n",
      "    File \"C:\\Users\\DELL\\AppData\\Roaming\\Python\\Python39\\site-packages\\keras\\src\\engine\\training.py\", line 2440, in predict_function  *\n",
      "        return step_function(self, iterator)\n",
      "    File \"C:\\Users\\DELL\\AppData\\Roaming\\Python\\Python39\\site-packages\\keras\\src\\engine\\training.py\", line 2425, in step_function  **\n",
      "        outputs = model.distribute_strategy.run(run_step, args=(data,))\n",
      "    File \"C:\\Users\\DELL\\AppData\\Roaming\\Python\\Python39\\site-packages\\keras\\src\\engine\\training.py\", line 2413, in run_step  **\n",
      "        outputs = model.predict_step(data)\n",
      "    File \"C:\\Users\\DELL\\AppData\\Roaming\\Python\\Python39\\site-packages\\keras\\src\\engine\\training.py\", line 2381, in predict_step\n",
      "        return self(x, training=False)\n",
      "    File \"C:\\Users\\DELL\\AppData\\Roaming\\Python\\Python39\\site-packages\\keras\\src\\utils\\traceback_utils.py\", line 70, in error_handler\n",
      "        raise e.with_traceback(filtered_tb) from None\n",
      "    File \"C:\\Users\\DELL\\AppData\\Roaming\\Python\\Python39\\site-packages\\keras\\src\\engine\\input_spec.py\", line 219, in assert_input_compatibility\n",
      "        raise ValueError(\n",
      "\n",
      "    ValueError: Layer \"model_2\" expects 2 input(s), but it received 1 input tensors. Inputs received: [<tf.Tensor 'IteratorGetNext:0' shape=(None, 48, 48, 3) dtype=float32>]\n",
      "\n",
      "ani wkeft\n",
      "Error during prediction: in user code:\n",
      "\n",
      "    File \"C:\\Users\\DELL\\AppData\\Roaming\\Python\\Python39\\site-packages\\keras\\src\\engine\\training.py\", line 2440, in predict_function  *\n",
      "        return step_function(self, iterator)\n",
      "    File \"C:\\Users\\DELL\\AppData\\Roaming\\Python\\Python39\\site-packages\\keras\\src\\engine\\training.py\", line 2425, in step_function  **\n",
      "        outputs = model.distribute_strategy.run(run_step, args=(data,))\n",
      "    File \"C:\\Users\\DELL\\AppData\\Roaming\\Python\\Python39\\site-packages\\keras\\src\\engine\\training.py\", line 2413, in run_step  **\n",
      "        outputs = model.predict_step(data)\n",
      "    File \"C:\\Users\\DELL\\AppData\\Roaming\\Python\\Python39\\site-packages\\keras\\src\\engine\\training.py\", line 2381, in predict_step\n",
      "        return self(x, training=False)\n",
      "    File \"C:\\Users\\DELL\\AppData\\Roaming\\Python\\Python39\\site-packages\\keras\\src\\utils\\traceback_utils.py\", line 70, in error_handler\n",
      "        raise e.with_traceback(filtered_tb) from None\n",
      "    File \"C:\\Users\\DELL\\AppData\\Roaming\\Python\\Python39\\site-packages\\keras\\src\\engine\\input_spec.py\", line 219, in assert_input_compatibility\n",
      "        raise ValueError(\n",
      "\n",
      "    ValueError: Layer \"model_2\" expects 2 input(s), but it received 1 input tensors. Inputs received: [<tf.Tensor 'IteratorGetNext:0' shape=(None, 48, 48, 3) dtype=float32>]\n",
      "\n",
      "ani wkeft\n",
      "Error during prediction: in user code:\n",
      "\n",
      "    File \"C:\\Users\\DELL\\AppData\\Roaming\\Python\\Python39\\site-packages\\keras\\src\\engine\\training.py\", line 2440, in predict_function  *\n",
      "        return step_function(self, iterator)\n",
      "    File \"C:\\Users\\DELL\\AppData\\Roaming\\Python\\Python39\\site-packages\\keras\\src\\engine\\training.py\", line 2425, in step_function  **\n",
      "        outputs = model.distribute_strategy.run(run_step, args=(data,))\n",
      "    File \"C:\\Users\\DELL\\AppData\\Roaming\\Python\\Python39\\site-packages\\keras\\src\\engine\\training.py\", line 2413, in run_step  **\n",
      "        outputs = model.predict_step(data)\n",
      "    File \"C:\\Users\\DELL\\AppData\\Roaming\\Python\\Python39\\site-packages\\keras\\src\\engine\\training.py\", line 2381, in predict_step\n",
      "        return self(x, training=False)\n",
      "    File \"C:\\Users\\DELL\\AppData\\Roaming\\Python\\Python39\\site-packages\\keras\\src\\utils\\traceback_utils.py\", line 70, in error_handler\n",
      "        raise e.with_traceback(filtered_tb) from None\n",
      "    File \"C:\\Users\\DELL\\AppData\\Roaming\\Python\\Python39\\site-packages\\keras\\src\\engine\\input_spec.py\", line 219, in assert_input_compatibility\n",
      "        raise ValueError(\n",
      "\n",
      "    ValueError: Layer \"model_2\" expects 2 input(s), but it received 1 input tensors. Inputs received: [<tf.Tensor 'IteratorGetNext:0' shape=(None, 48, 48, 3) dtype=float32>]\n",
      "\n",
      "ani wkeft\n",
      "Error during prediction: in user code:\n",
      "\n",
      "    File \"C:\\Users\\DELL\\AppData\\Roaming\\Python\\Python39\\site-packages\\keras\\src\\engine\\training.py\", line 2440, in predict_function  *\n",
      "        return step_function(self, iterator)\n",
      "    File \"C:\\Users\\DELL\\AppData\\Roaming\\Python\\Python39\\site-packages\\keras\\src\\engine\\training.py\", line 2425, in step_function  **\n",
      "        outputs = model.distribute_strategy.run(run_step, args=(data,))\n",
      "    File \"C:\\Users\\DELL\\AppData\\Roaming\\Python\\Python39\\site-packages\\keras\\src\\engine\\training.py\", line 2413, in run_step  **\n",
      "        outputs = model.predict_step(data)\n",
      "    File \"C:\\Users\\DELL\\AppData\\Roaming\\Python\\Python39\\site-packages\\keras\\src\\engine\\training.py\", line 2381, in predict_step\n",
      "        return self(x, training=False)\n",
      "    File \"C:\\Users\\DELL\\AppData\\Roaming\\Python\\Python39\\site-packages\\keras\\src\\utils\\traceback_utils.py\", line 70, in error_handler\n",
      "        raise e.with_traceback(filtered_tb) from None\n",
      "    File \"C:\\Users\\DELL\\AppData\\Roaming\\Python\\Python39\\site-packages\\keras\\src\\engine\\input_spec.py\", line 219, in assert_input_compatibility\n",
      "        raise ValueError(\n",
      "\n",
      "    ValueError: Layer \"model_2\" expects 2 input(s), but it received 1 input tensors. Inputs received: [<tf.Tensor 'IteratorGetNext:0' shape=(None, 48, 48, 3) dtype=float32>]\n",
      "\n",
      "ani wkeft\n",
      "Error during prediction: in user code:\n",
      "\n",
      "    File \"C:\\Users\\DELL\\AppData\\Roaming\\Python\\Python39\\site-packages\\keras\\src\\engine\\training.py\", line 2440, in predict_function  *\n",
      "        return step_function(self, iterator)\n",
      "    File \"C:\\Users\\DELL\\AppData\\Roaming\\Python\\Python39\\site-packages\\keras\\src\\engine\\training.py\", line 2425, in step_function  **\n",
      "        outputs = model.distribute_strategy.run(run_step, args=(data,))\n",
      "    File \"C:\\Users\\DELL\\AppData\\Roaming\\Python\\Python39\\site-packages\\keras\\src\\engine\\training.py\", line 2413, in run_step  **\n",
      "        outputs = model.predict_step(data)\n",
      "    File \"C:\\Users\\DELL\\AppData\\Roaming\\Python\\Python39\\site-packages\\keras\\src\\engine\\training.py\", line 2381, in predict_step\n",
      "        return self(x, training=False)\n",
      "    File \"C:\\Users\\DELL\\AppData\\Roaming\\Python\\Python39\\site-packages\\keras\\src\\utils\\traceback_utils.py\", line 70, in error_handler\n",
      "        raise e.with_traceback(filtered_tb) from None\n",
      "    File \"C:\\Users\\DELL\\AppData\\Roaming\\Python\\Python39\\site-packages\\keras\\src\\engine\\input_spec.py\", line 219, in assert_input_compatibility\n",
      "        raise ValueError(\n",
      "\n",
      "    ValueError: Layer \"model_2\" expects 2 input(s), but it received 1 input tensors. Inputs received: [<tf.Tensor 'IteratorGetNext:0' shape=(None, 48, 48, 3) dtype=float32>]\n",
      "\n",
      "ani wkeft\n",
      "Error during prediction: in user code:\n",
      "\n",
      "    File \"C:\\Users\\DELL\\AppData\\Roaming\\Python\\Python39\\site-packages\\keras\\src\\engine\\training.py\", line 2440, in predict_function  *\n",
      "        return step_function(self, iterator)\n",
      "    File \"C:\\Users\\DELL\\AppData\\Roaming\\Python\\Python39\\site-packages\\keras\\src\\engine\\training.py\", line 2425, in step_function  **\n",
      "        outputs = model.distribute_strategy.run(run_step, args=(data,))\n",
      "    File \"C:\\Users\\DELL\\AppData\\Roaming\\Python\\Python39\\site-packages\\keras\\src\\engine\\training.py\", line 2413, in run_step  **\n",
      "        outputs = model.predict_step(data)\n",
      "    File \"C:\\Users\\DELL\\AppData\\Roaming\\Python\\Python39\\site-packages\\keras\\src\\engine\\training.py\", line 2381, in predict_step\n",
      "        return self(x, training=False)\n",
      "    File \"C:\\Users\\DELL\\AppData\\Roaming\\Python\\Python39\\site-packages\\keras\\src\\utils\\traceback_utils.py\", line 70, in error_handler\n",
      "        raise e.with_traceback(filtered_tb) from None\n",
      "    File \"C:\\Users\\DELL\\AppData\\Roaming\\Python\\Python39\\site-packages\\keras\\src\\engine\\input_spec.py\", line 219, in assert_input_compatibility\n",
      "        raise ValueError(\n",
      "\n",
      "    ValueError: Layer \"model_2\" expects 2 input(s), but it received 1 input tensors. Inputs received: [<tf.Tensor 'IteratorGetNext:0' shape=(None, 48, 48, 3) dtype=float32>]\n",
      "\n",
      "ani wkeft\n",
      "Error during prediction: in user code:\n",
      "\n",
      "    File \"C:\\Users\\DELL\\AppData\\Roaming\\Python\\Python39\\site-packages\\keras\\src\\engine\\training.py\", line 2440, in predict_function  *\n",
      "        return step_function(self, iterator)\n",
      "    File \"C:\\Users\\DELL\\AppData\\Roaming\\Python\\Python39\\site-packages\\keras\\src\\engine\\training.py\", line 2425, in step_function  **\n",
      "        outputs = model.distribute_strategy.run(run_step, args=(data,))\n",
      "    File \"C:\\Users\\DELL\\AppData\\Roaming\\Python\\Python39\\site-packages\\keras\\src\\engine\\training.py\", line 2413, in run_step  **\n",
      "        outputs = model.predict_step(data)\n",
      "    File \"C:\\Users\\DELL\\AppData\\Roaming\\Python\\Python39\\site-packages\\keras\\src\\engine\\training.py\", line 2381, in predict_step\n",
      "        return self(x, training=False)\n",
      "    File \"C:\\Users\\DELL\\AppData\\Roaming\\Python\\Python39\\site-packages\\keras\\src\\utils\\traceback_utils.py\", line 70, in error_handler\n",
      "        raise e.with_traceback(filtered_tb) from None\n",
      "    File \"C:\\Users\\DELL\\AppData\\Roaming\\Python\\Python39\\site-packages\\keras\\src\\engine\\input_spec.py\", line 219, in assert_input_compatibility\n",
      "        raise ValueError(\n",
      "\n",
      "    ValueError: Layer \"model_2\" expects 2 input(s), but it received 1 input tensors. Inputs received: [<tf.Tensor 'IteratorGetNext:0' shape=(None, 48, 48, 3) dtype=float32>]\n",
      "\n",
      "ani wkeft\n",
      "Error during prediction: in user code:\n",
      "\n",
      "    File \"C:\\Users\\DELL\\AppData\\Roaming\\Python\\Python39\\site-packages\\keras\\src\\engine\\training.py\", line 2440, in predict_function  *\n",
      "        return step_function(self, iterator)\n",
      "    File \"C:\\Users\\DELL\\AppData\\Roaming\\Python\\Python39\\site-packages\\keras\\src\\engine\\training.py\", line 2425, in step_function  **\n",
      "        outputs = model.distribute_strategy.run(run_step, args=(data,))\n",
      "    File \"C:\\Users\\DELL\\AppData\\Roaming\\Python\\Python39\\site-packages\\keras\\src\\engine\\training.py\", line 2413, in run_step  **\n",
      "        outputs = model.predict_step(data)\n",
      "    File \"C:\\Users\\DELL\\AppData\\Roaming\\Python\\Python39\\site-packages\\keras\\src\\engine\\training.py\", line 2381, in predict_step\n",
      "        return self(x, training=False)\n",
      "    File \"C:\\Users\\DELL\\AppData\\Roaming\\Python\\Python39\\site-packages\\keras\\src\\utils\\traceback_utils.py\", line 70, in error_handler\n",
      "        raise e.with_traceback(filtered_tb) from None\n",
      "    File \"C:\\Users\\DELL\\AppData\\Roaming\\Python\\Python39\\site-packages\\keras\\src\\engine\\input_spec.py\", line 219, in assert_input_compatibility\n",
      "        raise ValueError(\n",
      "\n",
      "    ValueError: Layer \"model_2\" expects 2 input(s), but it received 1 input tensors. Inputs received: [<tf.Tensor 'IteratorGetNext:0' shape=(None, 48, 48, 3) dtype=float32>]\n",
      "\n",
      "ani wkeft\n",
      "Error during prediction: in user code:\n",
      "\n",
      "    File \"C:\\Users\\DELL\\AppData\\Roaming\\Python\\Python39\\site-packages\\keras\\src\\engine\\training.py\", line 2440, in predict_function  *\n",
      "        return step_function(self, iterator)\n",
      "    File \"C:\\Users\\DELL\\AppData\\Roaming\\Python\\Python39\\site-packages\\keras\\src\\engine\\training.py\", line 2425, in step_function  **\n",
      "        outputs = model.distribute_strategy.run(run_step, args=(data,))\n",
      "    File \"C:\\Users\\DELL\\AppData\\Roaming\\Python\\Python39\\site-packages\\keras\\src\\engine\\training.py\", line 2413, in run_step  **\n",
      "        outputs = model.predict_step(data)\n",
      "    File \"C:\\Users\\DELL\\AppData\\Roaming\\Python\\Python39\\site-packages\\keras\\src\\engine\\training.py\", line 2381, in predict_step\n",
      "        return self(x, training=False)\n",
      "    File \"C:\\Users\\DELL\\AppData\\Roaming\\Python\\Python39\\site-packages\\keras\\src\\utils\\traceback_utils.py\", line 70, in error_handler\n",
      "        raise e.with_traceback(filtered_tb) from None\n",
      "    File \"C:\\Users\\DELL\\AppData\\Roaming\\Python\\Python39\\site-packages\\keras\\src\\engine\\input_spec.py\", line 219, in assert_input_compatibility\n",
      "        raise ValueError(\n",
      "\n",
      "    ValueError: Layer \"model_2\" expects 2 input(s), but it received 1 input tensors. Inputs received: [<tf.Tensor 'IteratorGetNext:0' shape=(None, 48, 48, 3) dtype=float32>]\n",
      "\n",
      "ani wkeft\n",
      "Error during prediction: in user code:\n",
      "\n",
      "    File \"C:\\Users\\DELL\\AppData\\Roaming\\Python\\Python39\\site-packages\\keras\\src\\engine\\training.py\", line 2440, in predict_function  *\n",
      "        return step_function(self, iterator)\n",
      "    File \"C:\\Users\\DELL\\AppData\\Roaming\\Python\\Python39\\site-packages\\keras\\src\\engine\\training.py\", line 2425, in step_function  **\n",
      "        outputs = model.distribute_strategy.run(run_step, args=(data,))\n",
      "    File \"C:\\Users\\DELL\\AppData\\Roaming\\Python\\Python39\\site-packages\\keras\\src\\engine\\training.py\", line 2413, in run_step  **\n",
      "        outputs = model.predict_step(data)\n",
      "    File \"C:\\Users\\DELL\\AppData\\Roaming\\Python\\Python39\\site-packages\\keras\\src\\engine\\training.py\", line 2381, in predict_step\n",
      "        return self(x, training=False)\n",
      "    File \"C:\\Users\\DELL\\AppData\\Roaming\\Python\\Python39\\site-packages\\keras\\src\\utils\\traceback_utils.py\", line 70, in error_handler\n",
      "        raise e.with_traceback(filtered_tb) from None\n",
      "    File \"C:\\Users\\DELL\\AppData\\Roaming\\Python\\Python39\\site-packages\\keras\\src\\engine\\input_spec.py\", line 219, in assert_input_compatibility\n",
      "        raise ValueError(\n",
      "\n",
      "    ValueError: Layer \"model_2\" expects 2 input(s), but it received 1 input tensors. Inputs received: [<tf.Tensor 'IteratorGetNext:0' shape=(None, 48, 48, 3) dtype=float32>]\n",
      "\n",
      "ani wkeft\n",
      "Error during prediction: in user code:\n",
      "\n",
      "    File \"C:\\Users\\DELL\\AppData\\Roaming\\Python\\Python39\\site-packages\\keras\\src\\engine\\training.py\", line 2440, in predict_function  *\n",
      "        return step_function(self, iterator)\n",
      "    File \"C:\\Users\\DELL\\AppData\\Roaming\\Python\\Python39\\site-packages\\keras\\src\\engine\\training.py\", line 2425, in step_function  **\n",
      "        outputs = model.distribute_strategy.run(run_step, args=(data,))\n",
      "    File \"C:\\Users\\DELL\\AppData\\Roaming\\Python\\Python39\\site-packages\\keras\\src\\engine\\training.py\", line 2413, in run_step  **\n",
      "        outputs = model.predict_step(data)\n",
      "    File \"C:\\Users\\DELL\\AppData\\Roaming\\Python\\Python39\\site-packages\\keras\\src\\engine\\training.py\", line 2381, in predict_step\n",
      "        return self(x, training=False)\n",
      "    File \"C:\\Users\\DELL\\AppData\\Roaming\\Python\\Python39\\site-packages\\keras\\src\\utils\\traceback_utils.py\", line 70, in error_handler\n",
      "        raise e.with_traceback(filtered_tb) from None\n",
      "    File \"C:\\Users\\DELL\\AppData\\Roaming\\Python\\Python39\\site-packages\\keras\\src\\engine\\input_spec.py\", line 219, in assert_input_compatibility\n",
      "        raise ValueError(\n",
      "\n",
      "    ValueError: Layer \"model_2\" expects 2 input(s), but it received 1 input tensors. Inputs received: [<tf.Tensor 'IteratorGetNext:0' shape=(None, 48, 48, 3) dtype=float32>]\n",
      "\n",
      "ani wkeft\n",
      "Error during prediction: in user code:\n",
      "\n",
      "    File \"C:\\Users\\DELL\\AppData\\Roaming\\Python\\Python39\\site-packages\\keras\\src\\engine\\training.py\", line 2440, in predict_function  *\n",
      "        return step_function(self, iterator)\n",
      "    File \"C:\\Users\\DELL\\AppData\\Roaming\\Python\\Python39\\site-packages\\keras\\src\\engine\\training.py\", line 2425, in step_function  **\n",
      "        outputs = model.distribute_strategy.run(run_step, args=(data,))\n",
      "    File \"C:\\Users\\DELL\\AppData\\Roaming\\Python\\Python39\\site-packages\\keras\\src\\engine\\training.py\", line 2413, in run_step  **\n",
      "        outputs = model.predict_step(data)\n",
      "    File \"C:\\Users\\DELL\\AppData\\Roaming\\Python\\Python39\\site-packages\\keras\\src\\engine\\training.py\", line 2381, in predict_step\n",
      "        return self(x, training=False)\n",
      "    File \"C:\\Users\\DELL\\AppData\\Roaming\\Python\\Python39\\site-packages\\keras\\src\\utils\\traceback_utils.py\", line 70, in error_handler\n",
      "        raise e.with_traceback(filtered_tb) from None\n",
      "    File \"C:\\Users\\DELL\\AppData\\Roaming\\Python\\Python39\\site-packages\\keras\\src\\engine\\input_spec.py\", line 219, in assert_input_compatibility\n",
      "        raise ValueError(\n",
      "\n",
      "    ValueError: Layer \"model_2\" expects 2 input(s), but it received 1 input tensors. Inputs received: [<tf.Tensor 'IteratorGetNext:0' shape=(None, 48, 48, 3) dtype=float32>]\n",
      "\n",
      "ani wkeft\n",
      "Error during prediction: in user code:\n",
      "\n",
      "    File \"C:\\Users\\DELL\\AppData\\Roaming\\Python\\Python39\\site-packages\\keras\\src\\engine\\training.py\", line 2440, in predict_function  *\n",
      "        return step_function(self, iterator)\n",
      "    File \"C:\\Users\\DELL\\AppData\\Roaming\\Python\\Python39\\site-packages\\keras\\src\\engine\\training.py\", line 2425, in step_function  **\n",
      "        outputs = model.distribute_strategy.run(run_step, args=(data,))\n",
      "    File \"C:\\Users\\DELL\\AppData\\Roaming\\Python\\Python39\\site-packages\\keras\\src\\engine\\training.py\", line 2413, in run_step  **\n",
      "        outputs = model.predict_step(data)\n",
      "    File \"C:\\Users\\DELL\\AppData\\Roaming\\Python\\Python39\\site-packages\\keras\\src\\engine\\training.py\", line 2381, in predict_step\n",
      "        return self(x, training=False)\n",
      "    File \"C:\\Users\\DELL\\AppData\\Roaming\\Python\\Python39\\site-packages\\keras\\src\\utils\\traceback_utils.py\", line 70, in error_handler\n",
      "        raise e.with_traceback(filtered_tb) from None\n",
      "    File \"C:\\Users\\DELL\\AppData\\Roaming\\Python\\Python39\\site-packages\\keras\\src\\engine\\input_spec.py\", line 219, in assert_input_compatibility\n",
      "        raise ValueError(\n",
      "\n",
      "    ValueError: Layer \"model_2\" expects 2 input(s), but it received 1 input tensors. Inputs received: [<tf.Tensor 'IteratorGetNext:0' shape=(None, 48, 48, 3) dtype=float32>]\n",
      "\n",
      "ani wkeft\n",
      "Error during prediction: in user code:\n",
      "\n",
      "    File \"C:\\Users\\DELL\\AppData\\Roaming\\Python\\Python39\\site-packages\\keras\\src\\engine\\training.py\", line 2440, in predict_function  *\n",
      "        return step_function(self, iterator)\n",
      "    File \"C:\\Users\\DELL\\AppData\\Roaming\\Python\\Python39\\site-packages\\keras\\src\\engine\\training.py\", line 2425, in step_function  **\n",
      "        outputs = model.distribute_strategy.run(run_step, args=(data,))\n",
      "    File \"C:\\Users\\DELL\\AppData\\Roaming\\Python\\Python39\\site-packages\\keras\\src\\engine\\training.py\", line 2413, in run_step  **\n",
      "        outputs = model.predict_step(data)\n",
      "    File \"C:\\Users\\DELL\\AppData\\Roaming\\Python\\Python39\\site-packages\\keras\\src\\engine\\training.py\", line 2381, in predict_step\n",
      "        return self(x, training=False)\n",
      "    File \"C:\\Users\\DELL\\AppData\\Roaming\\Python\\Python39\\site-packages\\keras\\src\\utils\\traceback_utils.py\", line 70, in error_handler\n",
      "        raise e.with_traceback(filtered_tb) from None\n",
      "    File \"C:\\Users\\DELL\\AppData\\Roaming\\Python\\Python39\\site-packages\\keras\\src\\engine\\input_spec.py\", line 219, in assert_input_compatibility\n",
      "        raise ValueError(\n",
      "\n",
      "    ValueError: Layer \"model_2\" expects 2 input(s), but it received 1 input tensors. Inputs received: [<tf.Tensor 'IteratorGetNext:0' shape=(None, 48, 48, 3) dtype=float32>]\n",
      "\n",
      "ani wkeft\n",
      "Error during prediction: in user code:\n",
      "\n",
      "    File \"C:\\Users\\DELL\\AppData\\Roaming\\Python\\Python39\\site-packages\\keras\\src\\engine\\training.py\", line 2440, in predict_function  *\n",
      "        return step_function(self, iterator)\n",
      "    File \"C:\\Users\\DELL\\AppData\\Roaming\\Python\\Python39\\site-packages\\keras\\src\\engine\\training.py\", line 2425, in step_function  **\n",
      "        outputs = model.distribute_strategy.run(run_step, args=(data,))\n",
      "    File \"C:\\Users\\DELL\\AppData\\Roaming\\Python\\Python39\\site-packages\\keras\\src\\engine\\training.py\", line 2413, in run_step  **\n",
      "        outputs = model.predict_step(data)\n",
      "    File \"C:\\Users\\DELL\\AppData\\Roaming\\Python\\Python39\\site-packages\\keras\\src\\engine\\training.py\", line 2381, in predict_step\n",
      "        return self(x, training=False)\n",
      "    File \"C:\\Users\\DELL\\AppData\\Roaming\\Python\\Python39\\site-packages\\keras\\src\\utils\\traceback_utils.py\", line 70, in error_handler\n",
      "        raise e.with_traceback(filtered_tb) from None\n",
      "    File \"C:\\Users\\DELL\\AppData\\Roaming\\Python\\Python39\\site-packages\\keras\\src\\engine\\input_spec.py\", line 219, in assert_input_compatibility\n",
      "        raise ValueError(\n",
      "\n",
      "    ValueError: Layer \"model_2\" expects 2 input(s), but it received 1 input tensors. Inputs received: [<tf.Tensor 'IteratorGetNext:0' shape=(None, 48, 48, 3) dtype=float32>]\n",
      "\n",
      "ani wkeft\n",
      "Error during prediction: in user code:\n",
      "\n",
      "    File \"C:\\Users\\DELL\\AppData\\Roaming\\Python\\Python39\\site-packages\\keras\\src\\engine\\training.py\", line 2440, in predict_function  *\n",
      "        return step_function(self, iterator)\n",
      "    File \"C:\\Users\\DELL\\AppData\\Roaming\\Python\\Python39\\site-packages\\keras\\src\\engine\\training.py\", line 2425, in step_function  **\n",
      "        outputs = model.distribute_strategy.run(run_step, args=(data,))\n",
      "    File \"C:\\Users\\DELL\\AppData\\Roaming\\Python\\Python39\\site-packages\\keras\\src\\engine\\training.py\", line 2413, in run_step  **\n",
      "        outputs = model.predict_step(data)\n",
      "    File \"C:\\Users\\DELL\\AppData\\Roaming\\Python\\Python39\\site-packages\\keras\\src\\engine\\training.py\", line 2381, in predict_step\n",
      "        return self(x, training=False)\n",
      "    File \"C:\\Users\\DELL\\AppData\\Roaming\\Python\\Python39\\site-packages\\keras\\src\\utils\\traceback_utils.py\", line 70, in error_handler\n",
      "        raise e.with_traceback(filtered_tb) from None\n",
      "    File \"C:\\Users\\DELL\\AppData\\Roaming\\Python\\Python39\\site-packages\\keras\\src\\engine\\input_spec.py\", line 219, in assert_input_compatibility\n",
      "        raise ValueError(\n",
      "\n",
      "    ValueError: Layer \"model_2\" expects 2 input(s), but it received 1 input tensors. Inputs received: [<tf.Tensor 'IteratorGetNext:0' shape=(None, 48, 48, 3) dtype=float32>]\n",
      "\n",
      "ani wkeft\n",
      "Error during prediction: in user code:\n",
      "\n",
      "    File \"C:\\Users\\DELL\\AppData\\Roaming\\Python\\Python39\\site-packages\\keras\\src\\engine\\training.py\", line 2440, in predict_function  *\n",
      "        return step_function(self, iterator)\n",
      "    File \"C:\\Users\\DELL\\AppData\\Roaming\\Python\\Python39\\site-packages\\keras\\src\\engine\\training.py\", line 2425, in step_function  **\n",
      "        outputs = model.distribute_strategy.run(run_step, args=(data,))\n",
      "    File \"C:\\Users\\DELL\\AppData\\Roaming\\Python\\Python39\\site-packages\\keras\\src\\engine\\training.py\", line 2413, in run_step  **\n",
      "        outputs = model.predict_step(data)\n",
      "    File \"C:\\Users\\DELL\\AppData\\Roaming\\Python\\Python39\\site-packages\\keras\\src\\engine\\training.py\", line 2381, in predict_step\n",
      "        return self(x, training=False)\n",
      "    File \"C:\\Users\\DELL\\AppData\\Roaming\\Python\\Python39\\site-packages\\keras\\src\\utils\\traceback_utils.py\", line 70, in error_handler\n",
      "        raise e.with_traceback(filtered_tb) from None\n",
      "    File \"C:\\Users\\DELL\\AppData\\Roaming\\Python\\Python39\\site-packages\\keras\\src\\engine\\input_spec.py\", line 219, in assert_input_compatibility\n",
      "        raise ValueError(\n",
      "\n",
      "    ValueError: Layer \"model_2\" expects 2 input(s), but it received 1 input tensors. Inputs received: [<tf.Tensor 'IteratorGetNext:0' shape=(None, 48, 48, 3) dtype=float32>]\n",
      "\n",
      "ani wkeft\n",
      "Error during prediction: in user code:\n",
      "\n",
      "    File \"C:\\Users\\DELL\\AppData\\Roaming\\Python\\Python39\\site-packages\\keras\\src\\engine\\training.py\", line 2440, in predict_function  *\n",
      "        return step_function(self, iterator)\n",
      "    File \"C:\\Users\\DELL\\AppData\\Roaming\\Python\\Python39\\site-packages\\keras\\src\\engine\\training.py\", line 2425, in step_function  **\n",
      "        outputs = model.distribute_strategy.run(run_step, args=(data,))\n",
      "    File \"C:\\Users\\DELL\\AppData\\Roaming\\Python\\Python39\\site-packages\\keras\\src\\engine\\training.py\", line 2413, in run_step  **\n",
      "        outputs = model.predict_step(data)\n",
      "    File \"C:\\Users\\DELL\\AppData\\Roaming\\Python\\Python39\\site-packages\\keras\\src\\engine\\training.py\", line 2381, in predict_step\n",
      "        return self(x, training=False)\n",
      "    File \"C:\\Users\\DELL\\AppData\\Roaming\\Python\\Python39\\site-packages\\keras\\src\\utils\\traceback_utils.py\", line 70, in error_handler\n",
      "        raise e.with_traceback(filtered_tb) from None\n",
      "    File \"C:\\Users\\DELL\\AppData\\Roaming\\Python\\Python39\\site-packages\\keras\\src\\engine\\input_spec.py\", line 219, in assert_input_compatibility\n",
      "        raise ValueError(\n",
      "\n",
      "    ValueError: Layer \"model_2\" expects 2 input(s), but it received 1 input tensors. Inputs received: [<tf.Tensor 'IteratorGetNext:0' shape=(None, 48, 48, 3) dtype=float32>]\n",
      "\n",
      "ani wkeft\n",
      "Error during prediction: in user code:\n",
      "\n",
      "    File \"C:\\Users\\DELL\\AppData\\Roaming\\Python\\Python39\\site-packages\\keras\\src\\engine\\training.py\", line 2440, in predict_function  *\n",
      "        return step_function(self, iterator)\n",
      "    File \"C:\\Users\\DELL\\AppData\\Roaming\\Python\\Python39\\site-packages\\keras\\src\\engine\\training.py\", line 2425, in step_function  **\n",
      "        outputs = model.distribute_strategy.run(run_step, args=(data,))\n",
      "    File \"C:\\Users\\DELL\\AppData\\Roaming\\Python\\Python39\\site-packages\\keras\\src\\engine\\training.py\", line 2413, in run_step  **\n",
      "        outputs = model.predict_step(data)\n",
      "    File \"C:\\Users\\DELL\\AppData\\Roaming\\Python\\Python39\\site-packages\\keras\\src\\engine\\training.py\", line 2381, in predict_step\n",
      "        return self(x, training=False)\n",
      "    File \"C:\\Users\\DELL\\AppData\\Roaming\\Python\\Python39\\site-packages\\keras\\src\\utils\\traceback_utils.py\", line 70, in error_handler\n",
      "        raise e.with_traceback(filtered_tb) from None\n",
      "    File \"C:\\Users\\DELL\\AppData\\Roaming\\Python\\Python39\\site-packages\\keras\\src\\engine\\input_spec.py\", line 219, in assert_input_compatibility\n",
      "        raise ValueError(\n",
      "\n",
      "    ValueError: Layer \"model_2\" expects 2 input(s), but it received 1 input tensors. Inputs received: [<tf.Tensor 'IteratorGetNext:0' shape=(None, 48, 48, 3) dtype=float32>]\n",
      "\n",
      "ani wkeft\n",
      "Error during prediction: in user code:\n",
      "\n",
      "    File \"C:\\Users\\DELL\\AppData\\Roaming\\Python\\Python39\\site-packages\\keras\\src\\engine\\training.py\", line 2440, in predict_function  *\n",
      "        return step_function(self, iterator)\n",
      "    File \"C:\\Users\\DELL\\AppData\\Roaming\\Python\\Python39\\site-packages\\keras\\src\\engine\\training.py\", line 2425, in step_function  **\n",
      "        outputs = model.distribute_strategy.run(run_step, args=(data,))\n",
      "    File \"C:\\Users\\DELL\\AppData\\Roaming\\Python\\Python39\\site-packages\\keras\\src\\engine\\training.py\", line 2413, in run_step  **\n",
      "        outputs = model.predict_step(data)\n",
      "    File \"C:\\Users\\DELL\\AppData\\Roaming\\Python\\Python39\\site-packages\\keras\\src\\engine\\training.py\", line 2381, in predict_step\n",
      "        return self(x, training=False)\n",
      "    File \"C:\\Users\\DELL\\AppData\\Roaming\\Python\\Python39\\site-packages\\keras\\src\\utils\\traceback_utils.py\", line 70, in error_handler\n",
      "        raise e.with_traceback(filtered_tb) from None\n",
      "    File \"C:\\Users\\DELL\\AppData\\Roaming\\Python\\Python39\\site-packages\\keras\\src\\engine\\input_spec.py\", line 219, in assert_input_compatibility\n",
      "        raise ValueError(\n",
      "\n",
      "    ValueError: Layer \"model_2\" expects 2 input(s), but it received 1 input tensors. Inputs received: [<tf.Tensor 'IteratorGetNext:0' shape=(None, 48, 48, 3) dtype=float32>]\n",
      "\n",
      "ani wkeft\n",
      "Error during prediction: in user code:\n",
      "\n",
      "    File \"C:\\Users\\DELL\\AppData\\Roaming\\Python\\Python39\\site-packages\\keras\\src\\engine\\training.py\", line 2440, in predict_function  *\n",
      "        return step_function(self, iterator)\n",
      "    File \"C:\\Users\\DELL\\AppData\\Roaming\\Python\\Python39\\site-packages\\keras\\src\\engine\\training.py\", line 2425, in step_function  **\n",
      "        outputs = model.distribute_strategy.run(run_step, args=(data,))\n",
      "    File \"C:\\Users\\DELL\\AppData\\Roaming\\Python\\Python39\\site-packages\\keras\\src\\engine\\training.py\", line 2413, in run_step  **\n",
      "        outputs = model.predict_step(data)\n",
      "    File \"C:\\Users\\DELL\\AppData\\Roaming\\Python\\Python39\\site-packages\\keras\\src\\engine\\training.py\", line 2381, in predict_step\n",
      "        return self(x, training=False)\n",
      "    File \"C:\\Users\\DELL\\AppData\\Roaming\\Python\\Python39\\site-packages\\keras\\src\\utils\\traceback_utils.py\", line 70, in error_handler\n",
      "        raise e.with_traceback(filtered_tb) from None\n",
      "    File \"C:\\Users\\DELL\\AppData\\Roaming\\Python\\Python39\\site-packages\\keras\\src\\engine\\input_spec.py\", line 219, in assert_input_compatibility\n",
      "        raise ValueError(\n",
      "\n",
      "    ValueError: Layer \"model_2\" expects 2 input(s), but it received 1 input tensors. Inputs received: [<tf.Tensor 'IteratorGetNext:0' shape=(None, 48, 48, 3) dtype=float32>]\n",
      "\n",
      "ani wkeft\n",
      "Error during prediction: in user code:\n",
      "\n",
      "    File \"C:\\Users\\DELL\\AppData\\Roaming\\Python\\Python39\\site-packages\\keras\\src\\engine\\training.py\", line 2440, in predict_function  *\n",
      "        return step_function(self, iterator)\n",
      "    File \"C:\\Users\\DELL\\AppData\\Roaming\\Python\\Python39\\site-packages\\keras\\src\\engine\\training.py\", line 2425, in step_function  **\n",
      "        outputs = model.distribute_strategy.run(run_step, args=(data,))\n",
      "    File \"C:\\Users\\DELL\\AppData\\Roaming\\Python\\Python39\\site-packages\\keras\\src\\engine\\training.py\", line 2413, in run_step  **\n",
      "        outputs = model.predict_step(data)\n",
      "    File \"C:\\Users\\DELL\\AppData\\Roaming\\Python\\Python39\\site-packages\\keras\\src\\engine\\training.py\", line 2381, in predict_step\n",
      "        return self(x, training=False)\n",
      "    File \"C:\\Users\\DELL\\AppData\\Roaming\\Python\\Python39\\site-packages\\keras\\src\\utils\\traceback_utils.py\", line 70, in error_handler\n",
      "        raise e.with_traceback(filtered_tb) from None\n",
      "    File \"C:\\Users\\DELL\\AppData\\Roaming\\Python\\Python39\\site-packages\\keras\\src\\engine\\input_spec.py\", line 219, in assert_input_compatibility\n",
      "        raise ValueError(\n",
      "\n",
      "    ValueError: Layer \"model_2\" expects 2 input(s), but it received 1 input tensors. Inputs received: [<tf.Tensor 'IteratorGetNext:0' shape=(None, 48, 48, 3) dtype=float32>]\n",
      "\n",
      "ani wkeft\n",
      "Error during prediction: in user code:\n",
      "\n",
      "    File \"C:\\Users\\DELL\\AppData\\Roaming\\Python\\Python39\\site-packages\\keras\\src\\engine\\training.py\", line 2440, in predict_function  *\n",
      "        return step_function(self, iterator)\n",
      "    File \"C:\\Users\\DELL\\AppData\\Roaming\\Python\\Python39\\site-packages\\keras\\src\\engine\\training.py\", line 2425, in step_function  **\n",
      "        outputs = model.distribute_strategy.run(run_step, args=(data,))\n",
      "    File \"C:\\Users\\DELL\\AppData\\Roaming\\Python\\Python39\\site-packages\\keras\\src\\engine\\training.py\", line 2413, in run_step  **\n",
      "        outputs = model.predict_step(data)\n",
      "    File \"C:\\Users\\DELL\\AppData\\Roaming\\Python\\Python39\\site-packages\\keras\\src\\engine\\training.py\", line 2381, in predict_step\n",
      "        return self(x, training=False)\n",
      "    File \"C:\\Users\\DELL\\AppData\\Roaming\\Python\\Python39\\site-packages\\keras\\src\\utils\\traceback_utils.py\", line 70, in error_handler\n",
      "        raise e.with_traceback(filtered_tb) from None\n",
      "    File \"C:\\Users\\DELL\\AppData\\Roaming\\Python\\Python39\\site-packages\\keras\\src\\engine\\input_spec.py\", line 219, in assert_input_compatibility\n",
      "        raise ValueError(\n",
      "\n",
      "    ValueError: Layer \"model_2\" expects 2 input(s), but it received 1 input tensors. Inputs received: [<tf.Tensor 'IteratorGetNext:0' shape=(None, 48, 48, 3) dtype=float32>]\n",
      "\n",
      "ani wkeft\n",
      "Error during prediction: in user code:\n",
      "\n",
      "    File \"C:\\Users\\DELL\\AppData\\Roaming\\Python\\Python39\\site-packages\\keras\\src\\engine\\training.py\", line 2440, in predict_function  *\n",
      "        return step_function(self, iterator)\n",
      "    File \"C:\\Users\\DELL\\AppData\\Roaming\\Python\\Python39\\site-packages\\keras\\src\\engine\\training.py\", line 2425, in step_function  **\n",
      "        outputs = model.distribute_strategy.run(run_step, args=(data,))\n",
      "    File \"C:\\Users\\DELL\\AppData\\Roaming\\Python\\Python39\\site-packages\\keras\\src\\engine\\training.py\", line 2413, in run_step  **\n",
      "        outputs = model.predict_step(data)\n",
      "    File \"C:\\Users\\DELL\\AppData\\Roaming\\Python\\Python39\\site-packages\\keras\\src\\engine\\training.py\", line 2381, in predict_step\n",
      "        return self(x, training=False)\n",
      "    File \"C:\\Users\\DELL\\AppData\\Roaming\\Python\\Python39\\site-packages\\keras\\src\\utils\\traceback_utils.py\", line 70, in error_handler\n",
      "        raise e.with_traceback(filtered_tb) from None\n",
      "    File \"C:\\Users\\DELL\\AppData\\Roaming\\Python\\Python39\\site-packages\\keras\\src\\engine\\input_spec.py\", line 219, in assert_input_compatibility\n",
      "        raise ValueError(\n",
      "\n",
      "    ValueError: Layer \"model_2\" expects 2 input(s), but it received 1 input tensors. Inputs received: [<tf.Tensor 'IteratorGetNext:0' shape=(None, 48, 48, 3) dtype=float32>]\n",
      "\n",
      "ani wkeft\n",
      "Error during prediction: in user code:\n",
      "\n",
      "    File \"C:\\Users\\DELL\\AppData\\Roaming\\Python\\Python39\\site-packages\\keras\\src\\engine\\training.py\", line 2440, in predict_function  *\n",
      "        return step_function(self, iterator)\n",
      "    File \"C:\\Users\\DELL\\AppData\\Roaming\\Python\\Python39\\site-packages\\keras\\src\\engine\\training.py\", line 2425, in step_function  **\n",
      "        outputs = model.distribute_strategy.run(run_step, args=(data,))\n",
      "    File \"C:\\Users\\DELL\\AppData\\Roaming\\Python\\Python39\\site-packages\\keras\\src\\engine\\training.py\", line 2413, in run_step  **\n",
      "        outputs = model.predict_step(data)\n",
      "    File \"C:\\Users\\DELL\\AppData\\Roaming\\Python\\Python39\\site-packages\\keras\\src\\engine\\training.py\", line 2381, in predict_step\n",
      "        return self(x, training=False)\n",
      "    File \"C:\\Users\\DELL\\AppData\\Roaming\\Python\\Python39\\site-packages\\keras\\src\\utils\\traceback_utils.py\", line 70, in error_handler\n",
      "        raise e.with_traceback(filtered_tb) from None\n",
      "    File \"C:\\Users\\DELL\\AppData\\Roaming\\Python\\Python39\\site-packages\\keras\\src\\engine\\input_spec.py\", line 219, in assert_input_compatibility\n",
      "        raise ValueError(\n",
      "\n",
      "    ValueError: Layer \"model_2\" expects 2 input(s), but it received 1 input tensors. Inputs received: [<tf.Tensor 'IteratorGetNext:0' shape=(None, 48, 48, 3) dtype=float32>]\n",
      "\n",
      "ani wkeft\n",
      "Error during prediction: in user code:\n",
      "\n",
      "    File \"C:\\Users\\DELL\\AppData\\Roaming\\Python\\Python39\\site-packages\\keras\\src\\engine\\training.py\", line 2440, in predict_function  *\n",
      "        return step_function(self, iterator)\n",
      "    File \"C:\\Users\\DELL\\AppData\\Roaming\\Python\\Python39\\site-packages\\keras\\src\\engine\\training.py\", line 2425, in step_function  **\n",
      "        outputs = model.distribute_strategy.run(run_step, args=(data,))\n",
      "    File \"C:\\Users\\DELL\\AppData\\Roaming\\Python\\Python39\\site-packages\\keras\\src\\engine\\training.py\", line 2413, in run_step  **\n",
      "        outputs = model.predict_step(data)\n",
      "    File \"C:\\Users\\DELL\\AppData\\Roaming\\Python\\Python39\\site-packages\\keras\\src\\engine\\training.py\", line 2381, in predict_step\n",
      "        return self(x, training=False)\n",
      "    File \"C:\\Users\\DELL\\AppData\\Roaming\\Python\\Python39\\site-packages\\keras\\src\\utils\\traceback_utils.py\", line 70, in error_handler\n",
      "        raise e.with_traceback(filtered_tb) from None\n",
      "    File \"C:\\Users\\DELL\\AppData\\Roaming\\Python\\Python39\\site-packages\\keras\\src\\engine\\input_spec.py\", line 219, in assert_input_compatibility\n",
      "        raise ValueError(\n",
      "\n",
      "    ValueError: Layer \"model_2\" expects 2 input(s), but it received 1 input tensors. Inputs received: [<tf.Tensor 'IteratorGetNext:0' shape=(None, 48, 48, 3) dtype=float32>]\n",
      "\n",
      "ani wkeft\n",
      "Error during prediction: in user code:\n",
      "\n",
      "    File \"C:\\Users\\DELL\\AppData\\Roaming\\Python\\Python39\\site-packages\\keras\\src\\engine\\training.py\", line 2440, in predict_function  *\n",
      "        return step_function(self, iterator)\n",
      "    File \"C:\\Users\\DELL\\AppData\\Roaming\\Python\\Python39\\site-packages\\keras\\src\\engine\\training.py\", line 2425, in step_function  **\n",
      "        outputs = model.distribute_strategy.run(run_step, args=(data,))\n",
      "    File \"C:\\Users\\DELL\\AppData\\Roaming\\Python\\Python39\\site-packages\\keras\\src\\engine\\training.py\", line 2413, in run_step  **\n",
      "        outputs = model.predict_step(data)\n",
      "    File \"C:\\Users\\DELL\\AppData\\Roaming\\Python\\Python39\\site-packages\\keras\\src\\engine\\training.py\", line 2381, in predict_step\n",
      "        return self(x, training=False)\n",
      "    File \"C:\\Users\\DELL\\AppData\\Roaming\\Python\\Python39\\site-packages\\keras\\src\\utils\\traceback_utils.py\", line 70, in error_handler\n",
      "        raise e.with_traceback(filtered_tb) from None\n",
      "    File \"C:\\Users\\DELL\\AppData\\Roaming\\Python\\Python39\\site-packages\\keras\\src\\engine\\input_spec.py\", line 219, in assert_input_compatibility\n",
      "        raise ValueError(\n",
      "\n",
      "    ValueError: Layer \"model_2\" expects 2 input(s), but it received 1 input tensors. Inputs received: [<tf.Tensor 'IteratorGetNext:0' shape=(None, 48, 48, 3) dtype=float32>]\n",
      "\n",
      "ani wkeft\n",
      "Error during prediction: in user code:\n",
      "\n",
      "    File \"C:\\Users\\DELL\\AppData\\Roaming\\Python\\Python39\\site-packages\\keras\\src\\engine\\training.py\", line 2440, in predict_function  *\n",
      "        return step_function(self, iterator)\n",
      "    File \"C:\\Users\\DELL\\AppData\\Roaming\\Python\\Python39\\site-packages\\keras\\src\\engine\\training.py\", line 2425, in step_function  **\n",
      "        outputs = model.distribute_strategy.run(run_step, args=(data,))\n",
      "    File \"C:\\Users\\DELL\\AppData\\Roaming\\Python\\Python39\\site-packages\\keras\\src\\engine\\training.py\", line 2413, in run_step  **\n",
      "        outputs = model.predict_step(data)\n",
      "    File \"C:\\Users\\DELL\\AppData\\Roaming\\Python\\Python39\\site-packages\\keras\\src\\engine\\training.py\", line 2381, in predict_step\n",
      "        return self(x, training=False)\n",
      "    File \"C:\\Users\\DELL\\AppData\\Roaming\\Python\\Python39\\site-packages\\keras\\src\\utils\\traceback_utils.py\", line 70, in error_handler\n",
      "        raise e.with_traceback(filtered_tb) from None\n",
      "    File \"C:\\Users\\DELL\\AppData\\Roaming\\Python\\Python39\\site-packages\\keras\\src\\engine\\input_spec.py\", line 219, in assert_input_compatibility\n",
      "        raise ValueError(\n",
      "\n",
      "    ValueError: Layer \"model_2\" expects 2 input(s), but it received 1 input tensors. Inputs received: [<tf.Tensor 'IteratorGetNext:0' shape=(None, 48, 48, 3) dtype=float32>]\n",
      "\n",
      "ani wkeft\n",
      "Error during prediction: in user code:\n",
      "\n",
      "    File \"C:\\Users\\DELL\\AppData\\Roaming\\Python\\Python39\\site-packages\\keras\\src\\engine\\training.py\", line 2440, in predict_function  *\n",
      "        return step_function(self, iterator)\n",
      "    File \"C:\\Users\\DELL\\AppData\\Roaming\\Python\\Python39\\site-packages\\keras\\src\\engine\\training.py\", line 2425, in step_function  **\n",
      "        outputs = model.distribute_strategy.run(run_step, args=(data,))\n",
      "    File \"C:\\Users\\DELL\\AppData\\Roaming\\Python\\Python39\\site-packages\\keras\\src\\engine\\training.py\", line 2413, in run_step  **\n",
      "        outputs = model.predict_step(data)\n",
      "    File \"C:\\Users\\DELL\\AppData\\Roaming\\Python\\Python39\\site-packages\\keras\\src\\engine\\training.py\", line 2381, in predict_step\n",
      "        return self(x, training=False)\n",
      "    File \"C:\\Users\\DELL\\AppData\\Roaming\\Python\\Python39\\site-packages\\keras\\src\\utils\\traceback_utils.py\", line 70, in error_handler\n",
      "        raise e.with_traceback(filtered_tb) from None\n",
      "    File \"C:\\Users\\DELL\\AppData\\Roaming\\Python\\Python39\\site-packages\\keras\\src\\engine\\input_spec.py\", line 219, in assert_input_compatibility\n",
      "        raise ValueError(\n",
      "\n",
      "    ValueError: Layer \"model_2\" expects 2 input(s), but it received 1 input tensors. Inputs received: [<tf.Tensor 'IteratorGetNext:0' shape=(None, 48, 48, 3) dtype=float32>]\n",
      "\n",
      "ani wkeft\n",
      "Error during prediction: in user code:\n",
      "\n",
      "    File \"C:\\Users\\DELL\\AppData\\Roaming\\Python\\Python39\\site-packages\\keras\\src\\engine\\training.py\", line 2440, in predict_function  *\n",
      "        return step_function(self, iterator)\n",
      "    File \"C:\\Users\\DELL\\AppData\\Roaming\\Python\\Python39\\site-packages\\keras\\src\\engine\\training.py\", line 2425, in step_function  **\n",
      "        outputs = model.distribute_strategy.run(run_step, args=(data,))\n",
      "    File \"C:\\Users\\DELL\\AppData\\Roaming\\Python\\Python39\\site-packages\\keras\\src\\engine\\training.py\", line 2413, in run_step  **\n",
      "        outputs = model.predict_step(data)\n",
      "    File \"C:\\Users\\DELL\\AppData\\Roaming\\Python\\Python39\\site-packages\\keras\\src\\engine\\training.py\", line 2381, in predict_step\n",
      "        return self(x, training=False)\n",
      "    File \"C:\\Users\\DELL\\AppData\\Roaming\\Python\\Python39\\site-packages\\keras\\src\\utils\\traceback_utils.py\", line 70, in error_handler\n",
      "        raise e.with_traceback(filtered_tb) from None\n",
      "    File \"C:\\Users\\DELL\\AppData\\Roaming\\Python\\Python39\\site-packages\\keras\\src\\engine\\input_spec.py\", line 219, in assert_input_compatibility\n",
      "        raise ValueError(\n",
      "\n",
      "    ValueError: Layer \"model_2\" expects 2 input(s), but it received 1 input tensors. Inputs received: [<tf.Tensor 'IteratorGetNext:0' shape=(None, 48, 48, 3) dtype=float32>]\n",
      "\n",
      "ani wkeft\n",
      "Error during prediction: in user code:\n",
      "\n",
      "    File \"C:\\Users\\DELL\\AppData\\Roaming\\Python\\Python39\\site-packages\\keras\\src\\engine\\training.py\", line 2440, in predict_function  *\n",
      "        return step_function(self, iterator)\n",
      "    File \"C:\\Users\\DELL\\AppData\\Roaming\\Python\\Python39\\site-packages\\keras\\src\\engine\\training.py\", line 2425, in step_function  **\n",
      "        outputs = model.distribute_strategy.run(run_step, args=(data,))\n",
      "    File \"C:\\Users\\DELL\\AppData\\Roaming\\Python\\Python39\\site-packages\\keras\\src\\engine\\training.py\", line 2413, in run_step  **\n",
      "        outputs = model.predict_step(data)\n",
      "    File \"C:\\Users\\DELL\\AppData\\Roaming\\Python\\Python39\\site-packages\\keras\\src\\engine\\training.py\", line 2381, in predict_step\n",
      "        return self(x, training=False)\n",
      "    File \"C:\\Users\\DELL\\AppData\\Roaming\\Python\\Python39\\site-packages\\keras\\src\\utils\\traceback_utils.py\", line 70, in error_handler\n",
      "        raise e.with_traceback(filtered_tb) from None\n",
      "    File \"C:\\Users\\DELL\\AppData\\Roaming\\Python\\Python39\\site-packages\\keras\\src\\engine\\input_spec.py\", line 219, in assert_input_compatibility\n",
      "        raise ValueError(\n",
      "\n",
      "    ValueError: Layer \"model_2\" expects 2 input(s), but it received 1 input tensors. Inputs received: [<tf.Tensor 'IteratorGetNext:0' shape=(None, 48, 48, 3) dtype=float32>]\n",
      "\n",
      "ani wkeft\n",
      "Error during prediction: in user code:\n",
      "\n",
      "    File \"C:\\Users\\DELL\\AppData\\Roaming\\Python\\Python39\\site-packages\\keras\\src\\engine\\training.py\", line 2440, in predict_function  *\n",
      "        return step_function(self, iterator)\n",
      "    File \"C:\\Users\\DELL\\AppData\\Roaming\\Python\\Python39\\site-packages\\keras\\src\\engine\\training.py\", line 2425, in step_function  **\n",
      "        outputs = model.distribute_strategy.run(run_step, args=(data,))\n",
      "    File \"C:\\Users\\DELL\\AppData\\Roaming\\Python\\Python39\\site-packages\\keras\\src\\engine\\training.py\", line 2413, in run_step  **\n",
      "        outputs = model.predict_step(data)\n",
      "    File \"C:\\Users\\DELL\\AppData\\Roaming\\Python\\Python39\\site-packages\\keras\\src\\engine\\training.py\", line 2381, in predict_step\n",
      "        return self(x, training=False)\n",
      "    File \"C:\\Users\\DELL\\AppData\\Roaming\\Python\\Python39\\site-packages\\keras\\src\\utils\\traceback_utils.py\", line 70, in error_handler\n",
      "        raise e.with_traceback(filtered_tb) from None\n",
      "    File \"C:\\Users\\DELL\\AppData\\Roaming\\Python\\Python39\\site-packages\\keras\\src\\engine\\input_spec.py\", line 219, in assert_input_compatibility\n",
      "        raise ValueError(\n",
      "\n",
      "    ValueError: Layer \"model_2\" expects 2 input(s), but it received 1 input tensors. Inputs received: [<tf.Tensor 'IteratorGetNext:0' shape=(None, 48, 48, 3) dtype=float32>]\n",
      "\n",
      "ani wkeft\n",
      "Error during prediction: in user code:\n",
      "\n",
      "    File \"C:\\Users\\DELL\\AppData\\Roaming\\Python\\Python39\\site-packages\\keras\\src\\engine\\training.py\", line 2440, in predict_function  *\n",
      "        return step_function(self, iterator)\n",
      "    File \"C:\\Users\\DELL\\AppData\\Roaming\\Python\\Python39\\site-packages\\keras\\src\\engine\\training.py\", line 2425, in step_function  **\n",
      "        outputs = model.distribute_strategy.run(run_step, args=(data,))\n",
      "    File \"C:\\Users\\DELL\\AppData\\Roaming\\Python\\Python39\\site-packages\\keras\\src\\engine\\training.py\", line 2413, in run_step  **\n",
      "        outputs = model.predict_step(data)\n",
      "    File \"C:\\Users\\DELL\\AppData\\Roaming\\Python\\Python39\\site-packages\\keras\\src\\engine\\training.py\", line 2381, in predict_step\n",
      "        return self(x, training=False)\n",
      "    File \"C:\\Users\\DELL\\AppData\\Roaming\\Python\\Python39\\site-packages\\keras\\src\\utils\\traceback_utils.py\", line 70, in error_handler\n",
      "        raise e.with_traceback(filtered_tb) from None\n",
      "    File \"C:\\Users\\DELL\\AppData\\Roaming\\Python\\Python39\\site-packages\\keras\\src\\engine\\input_spec.py\", line 219, in assert_input_compatibility\n",
      "        raise ValueError(\n",
      "\n",
      "    ValueError: Layer \"model_2\" expects 2 input(s), but it received 1 input tensors. Inputs received: [<tf.Tensor 'IteratorGetNext:0' shape=(None, 48, 48, 3) dtype=float32>]\n",
      "\n",
      "ani wkeft\n",
      "Error during prediction: in user code:\n",
      "\n",
      "    File \"C:\\Users\\DELL\\AppData\\Roaming\\Python\\Python39\\site-packages\\keras\\src\\engine\\training.py\", line 2440, in predict_function  *\n",
      "        return step_function(self, iterator)\n",
      "    File \"C:\\Users\\DELL\\AppData\\Roaming\\Python\\Python39\\site-packages\\keras\\src\\engine\\training.py\", line 2425, in step_function  **\n",
      "        outputs = model.distribute_strategy.run(run_step, args=(data,))\n",
      "    File \"C:\\Users\\DELL\\AppData\\Roaming\\Python\\Python39\\site-packages\\keras\\src\\engine\\training.py\", line 2413, in run_step  **\n",
      "        outputs = model.predict_step(data)\n",
      "    File \"C:\\Users\\DELL\\AppData\\Roaming\\Python\\Python39\\site-packages\\keras\\src\\engine\\training.py\", line 2381, in predict_step\n",
      "        return self(x, training=False)\n",
      "    File \"C:\\Users\\DELL\\AppData\\Roaming\\Python\\Python39\\site-packages\\keras\\src\\utils\\traceback_utils.py\", line 70, in error_handler\n",
      "        raise e.with_traceback(filtered_tb) from None\n",
      "    File \"C:\\Users\\DELL\\AppData\\Roaming\\Python\\Python39\\site-packages\\keras\\src\\engine\\input_spec.py\", line 219, in assert_input_compatibility\n",
      "        raise ValueError(\n",
      "\n",
      "    ValueError: Layer \"model_2\" expects 2 input(s), but it received 1 input tensors. Inputs received: [<tf.Tensor 'IteratorGetNext:0' shape=(None, 48, 48, 3) dtype=float32>]\n",
      "\n",
      "ani wkeft\n",
      "Error during prediction: in user code:\n",
      "\n",
      "    File \"C:\\Users\\DELL\\AppData\\Roaming\\Python\\Python39\\site-packages\\keras\\src\\engine\\training.py\", line 2440, in predict_function  *\n",
      "        return step_function(self, iterator)\n",
      "    File \"C:\\Users\\DELL\\AppData\\Roaming\\Python\\Python39\\site-packages\\keras\\src\\engine\\training.py\", line 2425, in step_function  **\n",
      "        outputs = model.distribute_strategy.run(run_step, args=(data,))\n",
      "    File \"C:\\Users\\DELL\\AppData\\Roaming\\Python\\Python39\\site-packages\\keras\\src\\engine\\training.py\", line 2413, in run_step  **\n",
      "        outputs = model.predict_step(data)\n",
      "    File \"C:\\Users\\DELL\\AppData\\Roaming\\Python\\Python39\\site-packages\\keras\\src\\engine\\training.py\", line 2381, in predict_step\n",
      "        return self(x, training=False)\n",
      "    File \"C:\\Users\\DELL\\AppData\\Roaming\\Python\\Python39\\site-packages\\keras\\src\\utils\\traceback_utils.py\", line 70, in error_handler\n",
      "        raise e.with_traceback(filtered_tb) from None\n",
      "    File \"C:\\Users\\DELL\\AppData\\Roaming\\Python\\Python39\\site-packages\\keras\\src\\engine\\input_spec.py\", line 219, in assert_input_compatibility\n",
      "        raise ValueError(\n",
      "\n",
      "    ValueError: Layer \"model_2\" expects 2 input(s), but it received 1 input tensors. Inputs received: [<tf.Tensor 'IteratorGetNext:0' shape=(None, 48, 48, 3) dtype=float32>]\n",
      "\n",
      "ani wkeft\n",
      "Error during prediction: in user code:\n",
      "\n",
      "    File \"C:\\Users\\DELL\\AppData\\Roaming\\Python\\Python39\\site-packages\\keras\\src\\engine\\training.py\", line 2440, in predict_function  *\n",
      "        return step_function(self, iterator)\n",
      "    File \"C:\\Users\\DELL\\AppData\\Roaming\\Python\\Python39\\site-packages\\keras\\src\\engine\\training.py\", line 2425, in step_function  **\n",
      "        outputs = model.distribute_strategy.run(run_step, args=(data,))\n",
      "    File \"C:\\Users\\DELL\\AppData\\Roaming\\Python\\Python39\\site-packages\\keras\\src\\engine\\training.py\", line 2413, in run_step  **\n",
      "        outputs = model.predict_step(data)\n",
      "    File \"C:\\Users\\DELL\\AppData\\Roaming\\Python\\Python39\\site-packages\\keras\\src\\engine\\training.py\", line 2381, in predict_step\n",
      "        return self(x, training=False)\n",
      "    File \"C:\\Users\\DELL\\AppData\\Roaming\\Python\\Python39\\site-packages\\keras\\src\\utils\\traceback_utils.py\", line 70, in error_handler\n",
      "        raise e.with_traceback(filtered_tb) from None\n",
      "    File \"C:\\Users\\DELL\\AppData\\Roaming\\Python\\Python39\\site-packages\\keras\\src\\engine\\input_spec.py\", line 219, in assert_input_compatibility\n",
      "        raise ValueError(\n",
      "\n",
      "    ValueError: Layer \"model_2\" expects 2 input(s), but it received 1 input tensors. Inputs received: [<tf.Tensor 'IteratorGetNext:0' shape=(None, 48, 48, 3) dtype=float32>]\n",
      "\n",
      "ani wkeft\n",
      "Error during prediction: in user code:\n",
      "\n",
      "    File \"C:\\Users\\DELL\\AppData\\Roaming\\Python\\Python39\\site-packages\\keras\\src\\engine\\training.py\", line 2440, in predict_function  *\n",
      "        return step_function(self, iterator)\n",
      "    File \"C:\\Users\\DELL\\AppData\\Roaming\\Python\\Python39\\site-packages\\keras\\src\\engine\\training.py\", line 2425, in step_function  **\n",
      "        outputs = model.distribute_strategy.run(run_step, args=(data,))\n",
      "    File \"C:\\Users\\DELL\\AppData\\Roaming\\Python\\Python39\\site-packages\\keras\\src\\engine\\training.py\", line 2413, in run_step  **\n",
      "        outputs = model.predict_step(data)\n",
      "    File \"C:\\Users\\DELL\\AppData\\Roaming\\Python\\Python39\\site-packages\\keras\\src\\engine\\training.py\", line 2381, in predict_step\n",
      "        return self(x, training=False)\n",
      "    File \"C:\\Users\\DELL\\AppData\\Roaming\\Python\\Python39\\site-packages\\keras\\src\\utils\\traceback_utils.py\", line 70, in error_handler\n",
      "        raise e.with_traceback(filtered_tb) from None\n",
      "    File \"C:\\Users\\DELL\\AppData\\Roaming\\Python\\Python39\\site-packages\\keras\\src\\engine\\input_spec.py\", line 219, in assert_input_compatibility\n",
      "        raise ValueError(\n",
      "\n",
      "    ValueError: Layer \"model_2\" expects 2 input(s), but it received 1 input tensors. Inputs received: [<tf.Tensor 'IteratorGetNext:0' shape=(None, 48, 48, 3) dtype=float32>]\n",
      "\n",
      "ani wkeft\n",
      "Error during prediction: in user code:\n",
      "\n",
      "    File \"C:\\Users\\DELL\\AppData\\Roaming\\Python\\Python39\\site-packages\\keras\\src\\engine\\training.py\", line 2440, in predict_function  *\n",
      "        return step_function(self, iterator)\n",
      "    File \"C:\\Users\\DELL\\AppData\\Roaming\\Python\\Python39\\site-packages\\keras\\src\\engine\\training.py\", line 2425, in step_function  **\n",
      "        outputs = model.distribute_strategy.run(run_step, args=(data,))\n",
      "    File \"C:\\Users\\DELL\\AppData\\Roaming\\Python\\Python39\\site-packages\\keras\\src\\engine\\training.py\", line 2413, in run_step  **\n",
      "        outputs = model.predict_step(data)\n",
      "    File \"C:\\Users\\DELL\\AppData\\Roaming\\Python\\Python39\\site-packages\\keras\\src\\engine\\training.py\", line 2381, in predict_step\n",
      "        return self(x, training=False)\n",
      "    File \"C:\\Users\\DELL\\AppData\\Roaming\\Python\\Python39\\site-packages\\keras\\src\\utils\\traceback_utils.py\", line 70, in error_handler\n",
      "        raise e.with_traceback(filtered_tb) from None\n",
      "    File \"C:\\Users\\DELL\\AppData\\Roaming\\Python\\Python39\\site-packages\\keras\\src\\engine\\input_spec.py\", line 219, in assert_input_compatibility\n",
      "        raise ValueError(\n",
      "\n",
      "    ValueError: Layer \"model_2\" expects 2 input(s), but it received 1 input tensors. Inputs received: [<tf.Tensor 'IteratorGetNext:0' shape=(None, 48, 48, 3) dtype=float32>]\n",
      "\n",
      "ani wkeft\n",
      "Error during prediction: in user code:\n",
      "\n",
      "    File \"C:\\Users\\DELL\\AppData\\Roaming\\Python\\Python39\\site-packages\\keras\\src\\engine\\training.py\", line 2440, in predict_function  *\n",
      "        return step_function(self, iterator)\n",
      "    File \"C:\\Users\\DELL\\AppData\\Roaming\\Python\\Python39\\site-packages\\keras\\src\\engine\\training.py\", line 2425, in step_function  **\n",
      "        outputs = model.distribute_strategy.run(run_step, args=(data,))\n",
      "    File \"C:\\Users\\DELL\\AppData\\Roaming\\Python\\Python39\\site-packages\\keras\\src\\engine\\training.py\", line 2413, in run_step  **\n",
      "        outputs = model.predict_step(data)\n",
      "    File \"C:\\Users\\DELL\\AppData\\Roaming\\Python\\Python39\\site-packages\\keras\\src\\engine\\training.py\", line 2381, in predict_step\n",
      "        return self(x, training=False)\n",
      "    File \"C:\\Users\\DELL\\AppData\\Roaming\\Python\\Python39\\site-packages\\keras\\src\\utils\\traceback_utils.py\", line 70, in error_handler\n",
      "        raise e.with_traceback(filtered_tb) from None\n",
      "    File \"C:\\Users\\DELL\\AppData\\Roaming\\Python\\Python39\\site-packages\\keras\\src\\engine\\input_spec.py\", line 219, in assert_input_compatibility\n",
      "        raise ValueError(\n",
      "\n",
      "    ValueError: Layer \"model_2\" expects 2 input(s), but it received 1 input tensors. Inputs received: [<tf.Tensor 'IteratorGetNext:0' shape=(None, 48, 48, 3) dtype=float32>]\n",
      "\n",
      "ani wkeft\n",
      "Error during prediction: in user code:\n",
      "\n",
      "    File \"C:\\Users\\DELL\\AppData\\Roaming\\Python\\Python39\\site-packages\\keras\\src\\engine\\training.py\", line 2440, in predict_function  *\n",
      "        return step_function(self, iterator)\n",
      "    File \"C:\\Users\\DELL\\AppData\\Roaming\\Python\\Python39\\site-packages\\keras\\src\\engine\\training.py\", line 2425, in step_function  **\n",
      "        outputs = model.distribute_strategy.run(run_step, args=(data,))\n",
      "    File \"C:\\Users\\DELL\\AppData\\Roaming\\Python\\Python39\\site-packages\\keras\\src\\engine\\training.py\", line 2413, in run_step  **\n",
      "        outputs = model.predict_step(data)\n",
      "    File \"C:\\Users\\DELL\\AppData\\Roaming\\Python\\Python39\\site-packages\\keras\\src\\engine\\training.py\", line 2381, in predict_step\n",
      "        return self(x, training=False)\n",
      "    File \"C:\\Users\\DELL\\AppData\\Roaming\\Python\\Python39\\site-packages\\keras\\src\\utils\\traceback_utils.py\", line 70, in error_handler\n",
      "        raise e.with_traceback(filtered_tb) from None\n",
      "    File \"C:\\Users\\DELL\\AppData\\Roaming\\Python\\Python39\\site-packages\\keras\\src\\engine\\input_spec.py\", line 219, in assert_input_compatibility\n",
      "        raise ValueError(\n",
      "\n",
      "    ValueError: Layer \"model_2\" expects 2 input(s), but it received 1 input tensors. Inputs received: [<tf.Tensor 'IteratorGetNext:0' shape=(None, 48, 48, 3) dtype=float32>]\n",
      "\n",
      "ani wkeft\n",
      "Error during prediction: in user code:\n",
      "\n",
      "    File \"C:\\Users\\DELL\\AppData\\Roaming\\Python\\Python39\\site-packages\\keras\\src\\engine\\training.py\", line 2440, in predict_function  *\n",
      "        return step_function(self, iterator)\n",
      "    File \"C:\\Users\\DELL\\AppData\\Roaming\\Python\\Python39\\site-packages\\keras\\src\\engine\\training.py\", line 2425, in step_function  **\n",
      "        outputs = model.distribute_strategy.run(run_step, args=(data,))\n",
      "    File \"C:\\Users\\DELL\\AppData\\Roaming\\Python\\Python39\\site-packages\\keras\\src\\engine\\training.py\", line 2413, in run_step  **\n",
      "        outputs = model.predict_step(data)\n",
      "    File \"C:\\Users\\DELL\\AppData\\Roaming\\Python\\Python39\\site-packages\\keras\\src\\engine\\training.py\", line 2381, in predict_step\n",
      "        return self(x, training=False)\n",
      "    File \"C:\\Users\\DELL\\AppData\\Roaming\\Python\\Python39\\site-packages\\keras\\src\\utils\\traceback_utils.py\", line 70, in error_handler\n",
      "        raise e.with_traceback(filtered_tb) from None\n",
      "    File \"C:\\Users\\DELL\\AppData\\Roaming\\Python\\Python39\\site-packages\\keras\\src\\engine\\input_spec.py\", line 219, in assert_input_compatibility\n",
      "        raise ValueError(\n",
      "\n",
      "    ValueError: Layer \"model_2\" expects 2 input(s), but it received 1 input tensors. Inputs received: [<tf.Tensor 'IteratorGetNext:0' shape=(None, 48, 48, 3) dtype=float32>]\n",
      "\n",
      "ani wkeft\n",
      "Error during prediction: in user code:\n",
      "\n",
      "    File \"C:\\Users\\DELL\\AppData\\Roaming\\Python\\Python39\\site-packages\\keras\\src\\engine\\training.py\", line 2440, in predict_function  *\n",
      "        return step_function(self, iterator)\n",
      "    File \"C:\\Users\\DELL\\AppData\\Roaming\\Python\\Python39\\site-packages\\keras\\src\\engine\\training.py\", line 2425, in step_function  **\n",
      "        outputs = model.distribute_strategy.run(run_step, args=(data,))\n",
      "    File \"C:\\Users\\DELL\\AppData\\Roaming\\Python\\Python39\\site-packages\\keras\\src\\engine\\training.py\", line 2413, in run_step  **\n",
      "        outputs = model.predict_step(data)\n",
      "    File \"C:\\Users\\DELL\\AppData\\Roaming\\Python\\Python39\\site-packages\\keras\\src\\engine\\training.py\", line 2381, in predict_step\n",
      "        return self(x, training=False)\n",
      "    File \"C:\\Users\\DELL\\AppData\\Roaming\\Python\\Python39\\site-packages\\keras\\src\\utils\\traceback_utils.py\", line 70, in error_handler\n",
      "        raise e.with_traceback(filtered_tb) from None\n",
      "    File \"C:\\Users\\DELL\\AppData\\Roaming\\Python\\Python39\\site-packages\\keras\\src\\engine\\input_spec.py\", line 219, in assert_input_compatibility\n",
      "        raise ValueError(\n",
      "\n",
      "    ValueError: Layer \"model_2\" expects 2 input(s), but it received 1 input tensors. Inputs received: [<tf.Tensor 'IteratorGetNext:0' shape=(None, 48, 48, 3) dtype=float32>]\n",
      "\n",
      "ani wkeft\n",
      "Error during prediction: in user code:\n",
      "\n",
      "    File \"C:\\Users\\DELL\\AppData\\Roaming\\Python\\Python39\\site-packages\\keras\\src\\engine\\training.py\", line 2440, in predict_function  *\n",
      "        return step_function(self, iterator)\n",
      "    File \"C:\\Users\\DELL\\AppData\\Roaming\\Python\\Python39\\site-packages\\keras\\src\\engine\\training.py\", line 2425, in step_function  **\n",
      "        outputs = model.distribute_strategy.run(run_step, args=(data,))\n",
      "    File \"C:\\Users\\DELL\\AppData\\Roaming\\Python\\Python39\\site-packages\\keras\\src\\engine\\training.py\", line 2413, in run_step  **\n",
      "        outputs = model.predict_step(data)\n",
      "    File \"C:\\Users\\DELL\\AppData\\Roaming\\Python\\Python39\\site-packages\\keras\\src\\engine\\training.py\", line 2381, in predict_step\n",
      "        return self(x, training=False)\n",
      "    File \"C:\\Users\\DELL\\AppData\\Roaming\\Python\\Python39\\site-packages\\keras\\src\\utils\\traceback_utils.py\", line 70, in error_handler\n",
      "        raise e.with_traceback(filtered_tb) from None\n",
      "    File \"C:\\Users\\DELL\\AppData\\Roaming\\Python\\Python39\\site-packages\\keras\\src\\engine\\input_spec.py\", line 219, in assert_input_compatibility\n",
      "        raise ValueError(\n",
      "\n",
      "    ValueError: Layer \"model_2\" expects 2 input(s), but it received 1 input tensors. Inputs received: [<tf.Tensor 'IteratorGetNext:0' shape=(None, 48, 48, 3) dtype=float32>]\n",
      "\n",
      "ani wkeft\n",
      "Error during prediction: in user code:\n",
      "\n",
      "    File \"C:\\Users\\DELL\\AppData\\Roaming\\Python\\Python39\\site-packages\\keras\\src\\engine\\training.py\", line 2440, in predict_function  *\n",
      "        return step_function(self, iterator)\n",
      "    File \"C:\\Users\\DELL\\AppData\\Roaming\\Python\\Python39\\site-packages\\keras\\src\\engine\\training.py\", line 2425, in step_function  **\n",
      "        outputs = model.distribute_strategy.run(run_step, args=(data,))\n",
      "    File \"C:\\Users\\DELL\\AppData\\Roaming\\Python\\Python39\\site-packages\\keras\\src\\engine\\training.py\", line 2413, in run_step  **\n",
      "        outputs = model.predict_step(data)\n",
      "    File \"C:\\Users\\DELL\\AppData\\Roaming\\Python\\Python39\\site-packages\\keras\\src\\engine\\training.py\", line 2381, in predict_step\n",
      "        return self(x, training=False)\n",
      "    File \"C:\\Users\\DELL\\AppData\\Roaming\\Python\\Python39\\site-packages\\keras\\src\\utils\\traceback_utils.py\", line 70, in error_handler\n",
      "        raise e.with_traceback(filtered_tb) from None\n",
      "    File \"C:\\Users\\DELL\\AppData\\Roaming\\Python\\Python39\\site-packages\\keras\\src\\engine\\input_spec.py\", line 219, in assert_input_compatibility\n",
      "        raise ValueError(\n",
      "\n",
      "    ValueError: Layer \"model_2\" expects 2 input(s), but it received 1 input tensors. Inputs received: [<tf.Tensor 'IteratorGetNext:0' shape=(None, 48, 48, 3) dtype=float32>]\n",
      "\n",
      "ani wkeft\n",
      "Error during prediction: in user code:\n",
      "\n",
      "    File \"C:\\Users\\DELL\\AppData\\Roaming\\Python\\Python39\\site-packages\\keras\\src\\engine\\training.py\", line 2440, in predict_function  *\n",
      "        return step_function(self, iterator)\n",
      "    File \"C:\\Users\\DELL\\AppData\\Roaming\\Python\\Python39\\site-packages\\keras\\src\\engine\\training.py\", line 2425, in step_function  **\n",
      "        outputs = model.distribute_strategy.run(run_step, args=(data,))\n",
      "    File \"C:\\Users\\DELL\\AppData\\Roaming\\Python\\Python39\\site-packages\\keras\\src\\engine\\training.py\", line 2413, in run_step  **\n",
      "        outputs = model.predict_step(data)\n",
      "    File \"C:\\Users\\DELL\\AppData\\Roaming\\Python\\Python39\\site-packages\\keras\\src\\engine\\training.py\", line 2381, in predict_step\n",
      "        return self(x, training=False)\n",
      "    File \"C:\\Users\\DELL\\AppData\\Roaming\\Python\\Python39\\site-packages\\keras\\src\\utils\\traceback_utils.py\", line 70, in error_handler\n",
      "        raise e.with_traceback(filtered_tb) from None\n",
      "    File \"C:\\Users\\DELL\\AppData\\Roaming\\Python\\Python39\\site-packages\\keras\\src\\engine\\input_spec.py\", line 219, in assert_input_compatibility\n",
      "        raise ValueError(\n",
      "\n",
      "    ValueError: Layer \"model_2\" expects 2 input(s), but it received 1 input tensors. Inputs received: [<tf.Tensor 'IteratorGetNext:0' shape=(None, 48, 48, 3) dtype=float32>]\n",
      "\n",
      "ani wkeft\n",
      "Error during prediction: in user code:\n",
      "\n",
      "    File \"C:\\Users\\DELL\\AppData\\Roaming\\Python\\Python39\\site-packages\\keras\\src\\engine\\training.py\", line 2440, in predict_function  *\n",
      "        return step_function(self, iterator)\n",
      "    File \"C:\\Users\\DELL\\AppData\\Roaming\\Python\\Python39\\site-packages\\keras\\src\\engine\\training.py\", line 2425, in step_function  **\n",
      "        outputs = model.distribute_strategy.run(run_step, args=(data,))\n",
      "    File \"C:\\Users\\DELL\\AppData\\Roaming\\Python\\Python39\\site-packages\\keras\\src\\engine\\training.py\", line 2413, in run_step  **\n",
      "        outputs = model.predict_step(data)\n",
      "    File \"C:\\Users\\DELL\\AppData\\Roaming\\Python\\Python39\\site-packages\\keras\\src\\engine\\training.py\", line 2381, in predict_step\n",
      "        return self(x, training=False)\n",
      "    File \"C:\\Users\\DELL\\AppData\\Roaming\\Python\\Python39\\site-packages\\keras\\src\\utils\\traceback_utils.py\", line 70, in error_handler\n",
      "        raise e.with_traceback(filtered_tb) from None\n",
      "    File \"C:\\Users\\DELL\\AppData\\Roaming\\Python\\Python39\\site-packages\\keras\\src\\engine\\input_spec.py\", line 219, in assert_input_compatibility\n",
      "        raise ValueError(\n",
      "\n",
      "    ValueError: Layer \"model_2\" expects 2 input(s), but it received 1 input tensors. Inputs received: [<tf.Tensor 'IteratorGetNext:0' shape=(None, 48, 48, 3) dtype=float32>]\n",
      "\n",
      "ani wkeft\n",
      "Error during prediction: in user code:\n",
      "\n",
      "    File \"C:\\Users\\DELL\\AppData\\Roaming\\Python\\Python39\\site-packages\\keras\\src\\engine\\training.py\", line 2440, in predict_function  *\n",
      "        return step_function(self, iterator)\n",
      "    File \"C:\\Users\\DELL\\AppData\\Roaming\\Python\\Python39\\site-packages\\keras\\src\\engine\\training.py\", line 2425, in step_function  **\n",
      "        outputs = model.distribute_strategy.run(run_step, args=(data,))\n",
      "    File \"C:\\Users\\DELL\\AppData\\Roaming\\Python\\Python39\\site-packages\\keras\\src\\engine\\training.py\", line 2413, in run_step  **\n",
      "        outputs = model.predict_step(data)\n",
      "    File \"C:\\Users\\DELL\\AppData\\Roaming\\Python\\Python39\\site-packages\\keras\\src\\engine\\training.py\", line 2381, in predict_step\n",
      "        return self(x, training=False)\n",
      "    File \"C:\\Users\\DELL\\AppData\\Roaming\\Python\\Python39\\site-packages\\keras\\src\\utils\\traceback_utils.py\", line 70, in error_handler\n",
      "        raise e.with_traceback(filtered_tb) from None\n",
      "    File \"C:\\Users\\DELL\\AppData\\Roaming\\Python\\Python39\\site-packages\\keras\\src\\engine\\input_spec.py\", line 219, in assert_input_compatibility\n",
      "        raise ValueError(\n",
      "\n",
      "    ValueError: Layer \"model_2\" expects 2 input(s), but it received 1 input tensors. Inputs received: [<tf.Tensor 'IteratorGetNext:0' shape=(None, 48, 48, 3) dtype=float32>]\n",
      "\n",
      "ani wkeft\n",
      "Error during prediction: in user code:\n",
      "\n",
      "    File \"C:\\Users\\DELL\\AppData\\Roaming\\Python\\Python39\\site-packages\\keras\\src\\engine\\training.py\", line 2440, in predict_function  *\n",
      "        return step_function(self, iterator)\n",
      "    File \"C:\\Users\\DELL\\AppData\\Roaming\\Python\\Python39\\site-packages\\keras\\src\\engine\\training.py\", line 2425, in step_function  **\n",
      "        outputs = model.distribute_strategy.run(run_step, args=(data,))\n",
      "    File \"C:\\Users\\DELL\\AppData\\Roaming\\Python\\Python39\\site-packages\\keras\\src\\engine\\training.py\", line 2413, in run_step  **\n",
      "        outputs = model.predict_step(data)\n",
      "    File \"C:\\Users\\DELL\\AppData\\Roaming\\Python\\Python39\\site-packages\\keras\\src\\engine\\training.py\", line 2381, in predict_step\n",
      "        return self(x, training=False)\n",
      "    File \"C:\\Users\\DELL\\AppData\\Roaming\\Python\\Python39\\site-packages\\keras\\src\\utils\\traceback_utils.py\", line 70, in error_handler\n",
      "        raise e.with_traceback(filtered_tb) from None\n",
      "    File \"C:\\Users\\DELL\\AppData\\Roaming\\Python\\Python39\\site-packages\\keras\\src\\engine\\input_spec.py\", line 219, in assert_input_compatibility\n",
      "        raise ValueError(\n",
      "\n",
      "    ValueError: Layer \"model_2\" expects 2 input(s), but it received 1 input tensors. Inputs received: [<tf.Tensor 'IteratorGetNext:0' shape=(None, 48, 48, 3) dtype=float32>]\n",
      "\n",
      "ani wkeft\n",
      "Error during prediction: in user code:\n",
      "\n",
      "    File \"C:\\Users\\DELL\\AppData\\Roaming\\Python\\Python39\\site-packages\\keras\\src\\engine\\training.py\", line 2440, in predict_function  *\n",
      "        return step_function(self, iterator)\n",
      "    File \"C:\\Users\\DELL\\AppData\\Roaming\\Python\\Python39\\site-packages\\keras\\src\\engine\\training.py\", line 2425, in step_function  **\n",
      "        outputs = model.distribute_strategy.run(run_step, args=(data,))\n",
      "    File \"C:\\Users\\DELL\\AppData\\Roaming\\Python\\Python39\\site-packages\\keras\\src\\engine\\training.py\", line 2413, in run_step  **\n",
      "        outputs = model.predict_step(data)\n",
      "    File \"C:\\Users\\DELL\\AppData\\Roaming\\Python\\Python39\\site-packages\\keras\\src\\engine\\training.py\", line 2381, in predict_step\n",
      "        return self(x, training=False)\n",
      "    File \"C:\\Users\\DELL\\AppData\\Roaming\\Python\\Python39\\site-packages\\keras\\src\\utils\\traceback_utils.py\", line 70, in error_handler\n",
      "        raise e.with_traceback(filtered_tb) from None\n",
      "    File \"C:\\Users\\DELL\\AppData\\Roaming\\Python\\Python39\\site-packages\\keras\\src\\engine\\input_spec.py\", line 219, in assert_input_compatibility\n",
      "        raise ValueError(\n",
      "\n",
      "    ValueError: Layer \"model_2\" expects 2 input(s), but it received 1 input tensors. Inputs received: [<tf.Tensor 'IteratorGetNext:0' shape=(None, 48, 48, 3) dtype=float32>]\n",
      "\n",
      "ani wkeft\n",
      "Error during prediction: in user code:\n",
      "\n",
      "    File \"C:\\Users\\DELL\\AppData\\Roaming\\Python\\Python39\\site-packages\\keras\\src\\engine\\training.py\", line 2440, in predict_function  *\n",
      "        return step_function(self, iterator)\n",
      "    File \"C:\\Users\\DELL\\AppData\\Roaming\\Python\\Python39\\site-packages\\keras\\src\\engine\\training.py\", line 2425, in step_function  **\n",
      "        outputs = model.distribute_strategy.run(run_step, args=(data,))\n",
      "    File \"C:\\Users\\DELL\\AppData\\Roaming\\Python\\Python39\\site-packages\\keras\\src\\engine\\training.py\", line 2413, in run_step  **\n",
      "        outputs = model.predict_step(data)\n",
      "    File \"C:\\Users\\DELL\\AppData\\Roaming\\Python\\Python39\\site-packages\\keras\\src\\engine\\training.py\", line 2381, in predict_step\n",
      "        return self(x, training=False)\n",
      "    File \"C:\\Users\\DELL\\AppData\\Roaming\\Python\\Python39\\site-packages\\keras\\src\\utils\\traceback_utils.py\", line 70, in error_handler\n",
      "        raise e.with_traceback(filtered_tb) from None\n",
      "    File \"C:\\Users\\DELL\\AppData\\Roaming\\Python\\Python39\\site-packages\\keras\\src\\engine\\input_spec.py\", line 219, in assert_input_compatibility\n",
      "        raise ValueError(\n",
      "\n",
      "    ValueError: Layer \"model_2\" expects 2 input(s), but it received 1 input tensors. Inputs received: [<tf.Tensor 'IteratorGetNext:0' shape=(None, 48, 48, 3) dtype=float32>]\n",
      "\n",
      "ani wkeft\n",
      "Error during prediction: in user code:\n",
      "\n",
      "    File \"C:\\Users\\DELL\\AppData\\Roaming\\Python\\Python39\\site-packages\\keras\\src\\engine\\training.py\", line 2440, in predict_function  *\n",
      "        return step_function(self, iterator)\n",
      "    File \"C:\\Users\\DELL\\AppData\\Roaming\\Python\\Python39\\site-packages\\keras\\src\\engine\\training.py\", line 2425, in step_function  **\n",
      "        outputs = model.distribute_strategy.run(run_step, args=(data,))\n",
      "    File \"C:\\Users\\DELL\\AppData\\Roaming\\Python\\Python39\\site-packages\\keras\\src\\engine\\training.py\", line 2413, in run_step  **\n",
      "        outputs = model.predict_step(data)\n",
      "    File \"C:\\Users\\DELL\\AppData\\Roaming\\Python\\Python39\\site-packages\\keras\\src\\engine\\training.py\", line 2381, in predict_step\n",
      "        return self(x, training=False)\n",
      "    File \"C:\\Users\\DELL\\AppData\\Roaming\\Python\\Python39\\site-packages\\keras\\src\\utils\\traceback_utils.py\", line 70, in error_handler\n",
      "        raise e.with_traceback(filtered_tb) from None\n",
      "    File \"C:\\Users\\DELL\\AppData\\Roaming\\Python\\Python39\\site-packages\\keras\\src\\engine\\input_spec.py\", line 219, in assert_input_compatibility\n",
      "        raise ValueError(\n",
      "\n",
      "    ValueError: Layer \"model_2\" expects 2 input(s), but it received 1 input tensors. Inputs received: [<tf.Tensor 'IteratorGetNext:0' shape=(None, 48, 48, 3) dtype=float32>]\n",
      "\n",
      "ani wkeft\n",
      "Error during prediction: in user code:\n",
      "\n",
      "    File \"C:\\Users\\DELL\\AppData\\Roaming\\Python\\Python39\\site-packages\\keras\\src\\engine\\training.py\", line 2440, in predict_function  *\n",
      "        return step_function(self, iterator)\n",
      "    File \"C:\\Users\\DELL\\AppData\\Roaming\\Python\\Python39\\site-packages\\keras\\src\\engine\\training.py\", line 2425, in step_function  **\n",
      "        outputs = model.distribute_strategy.run(run_step, args=(data,))\n",
      "    File \"C:\\Users\\DELL\\AppData\\Roaming\\Python\\Python39\\site-packages\\keras\\src\\engine\\training.py\", line 2413, in run_step  **\n",
      "        outputs = model.predict_step(data)\n",
      "    File \"C:\\Users\\DELL\\AppData\\Roaming\\Python\\Python39\\site-packages\\keras\\src\\engine\\training.py\", line 2381, in predict_step\n",
      "        return self(x, training=False)\n",
      "    File \"C:\\Users\\DELL\\AppData\\Roaming\\Python\\Python39\\site-packages\\keras\\src\\utils\\traceback_utils.py\", line 70, in error_handler\n",
      "        raise e.with_traceback(filtered_tb) from None\n",
      "    File \"C:\\Users\\DELL\\AppData\\Roaming\\Python\\Python39\\site-packages\\keras\\src\\engine\\input_spec.py\", line 219, in assert_input_compatibility\n",
      "        raise ValueError(\n",
      "\n",
      "    ValueError: Layer \"model_2\" expects 2 input(s), but it received 1 input tensors. Inputs received: [<tf.Tensor 'IteratorGetNext:0' shape=(None, 48, 48, 3) dtype=float32>]\n",
      "\n",
      "ani wkeft\n",
      "Error during prediction: in user code:\n",
      "\n",
      "    File \"C:\\Users\\DELL\\AppData\\Roaming\\Python\\Python39\\site-packages\\keras\\src\\engine\\training.py\", line 2440, in predict_function  *\n",
      "        return step_function(self, iterator)\n",
      "    File \"C:\\Users\\DELL\\AppData\\Roaming\\Python\\Python39\\site-packages\\keras\\src\\engine\\training.py\", line 2425, in step_function  **\n",
      "        outputs = model.distribute_strategy.run(run_step, args=(data,))\n",
      "    File \"C:\\Users\\DELL\\AppData\\Roaming\\Python\\Python39\\site-packages\\keras\\src\\engine\\training.py\", line 2413, in run_step  **\n",
      "        outputs = model.predict_step(data)\n",
      "    File \"C:\\Users\\DELL\\AppData\\Roaming\\Python\\Python39\\site-packages\\keras\\src\\engine\\training.py\", line 2381, in predict_step\n",
      "        return self(x, training=False)\n",
      "    File \"C:\\Users\\DELL\\AppData\\Roaming\\Python\\Python39\\site-packages\\keras\\src\\utils\\traceback_utils.py\", line 70, in error_handler\n",
      "        raise e.with_traceback(filtered_tb) from None\n",
      "    File \"C:\\Users\\DELL\\AppData\\Roaming\\Python\\Python39\\site-packages\\keras\\src\\engine\\input_spec.py\", line 219, in assert_input_compatibility\n",
      "        raise ValueError(\n",
      "\n",
      "    ValueError: Layer \"model_2\" expects 2 input(s), but it received 1 input tensors. Inputs received: [<tf.Tensor 'IteratorGetNext:0' shape=(None, 48, 48, 3) dtype=float32>]\n",
      "\n",
      "ani wkeft\n",
      "Error during prediction: in user code:\n",
      "\n",
      "    File \"C:\\Users\\DELL\\AppData\\Roaming\\Python\\Python39\\site-packages\\keras\\src\\engine\\training.py\", line 2440, in predict_function  *\n",
      "        return step_function(self, iterator)\n",
      "    File \"C:\\Users\\DELL\\AppData\\Roaming\\Python\\Python39\\site-packages\\keras\\src\\engine\\training.py\", line 2425, in step_function  **\n",
      "        outputs = model.distribute_strategy.run(run_step, args=(data,))\n",
      "    File \"C:\\Users\\DELL\\AppData\\Roaming\\Python\\Python39\\site-packages\\keras\\src\\engine\\training.py\", line 2413, in run_step  **\n",
      "        outputs = model.predict_step(data)\n",
      "    File \"C:\\Users\\DELL\\AppData\\Roaming\\Python\\Python39\\site-packages\\keras\\src\\engine\\training.py\", line 2381, in predict_step\n",
      "        return self(x, training=False)\n",
      "    File \"C:\\Users\\DELL\\AppData\\Roaming\\Python\\Python39\\site-packages\\keras\\src\\utils\\traceback_utils.py\", line 70, in error_handler\n",
      "        raise e.with_traceback(filtered_tb) from None\n",
      "    File \"C:\\Users\\DELL\\AppData\\Roaming\\Python\\Python39\\site-packages\\keras\\src\\engine\\input_spec.py\", line 219, in assert_input_compatibility\n",
      "        raise ValueError(\n",
      "\n",
      "    ValueError: Layer \"model_2\" expects 2 input(s), but it received 1 input tensors. Inputs received: [<tf.Tensor 'IteratorGetNext:0' shape=(None, 48, 48, 3) dtype=float32>]\n",
      "\n",
      "ani wkeft\n",
      "Error during prediction: in user code:\n",
      "\n",
      "    File \"C:\\Users\\DELL\\AppData\\Roaming\\Python\\Python39\\site-packages\\keras\\src\\engine\\training.py\", line 2440, in predict_function  *\n",
      "        return step_function(self, iterator)\n",
      "    File \"C:\\Users\\DELL\\AppData\\Roaming\\Python\\Python39\\site-packages\\keras\\src\\engine\\training.py\", line 2425, in step_function  **\n",
      "        outputs = model.distribute_strategy.run(run_step, args=(data,))\n",
      "    File \"C:\\Users\\DELL\\AppData\\Roaming\\Python\\Python39\\site-packages\\keras\\src\\engine\\training.py\", line 2413, in run_step  **\n",
      "        outputs = model.predict_step(data)\n",
      "    File \"C:\\Users\\DELL\\AppData\\Roaming\\Python\\Python39\\site-packages\\keras\\src\\engine\\training.py\", line 2381, in predict_step\n",
      "        return self(x, training=False)\n",
      "    File \"C:\\Users\\DELL\\AppData\\Roaming\\Python\\Python39\\site-packages\\keras\\src\\utils\\traceback_utils.py\", line 70, in error_handler\n",
      "        raise e.with_traceback(filtered_tb) from None\n",
      "    File \"C:\\Users\\DELL\\AppData\\Roaming\\Python\\Python39\\site-packages\\keras\\src\\engine\\input_spec.py\", line 219, in assert_input_compatibility\n",
      "        raise ValueError(\n",
      "\n",
      "    ValueError: Layer \"model_2\" expects 2 input(s), but it received 1 input tensors. Inputs received: [<tf.Tensor 'IteratorGetNext:0' shape=(None, 48, 48, 3) dtype=float32>]\n",
      "\n",
      "ani wkeft\n",
      "Error during prediction: in user code:\n",
      "\n",
      "    File \"C:\\Users\\DELL\\AppData\\Roaming\\Python\\Python39\\site-packages\\keras\\src\\engine\\training.py\", line 2440, in predict_function  *\n",
      "        return step_function(self, iterator)\n",
      "    File \"C:\\Users\\DELL\\AppData\\Roaming\\Python\\Python39\\site-packages\\keras\\src\\engine\\training.py\", line 2425, in step_function  **\n",
      "        outputs = model.distribute_strategy.run(run_step, args=(data,))\n",
      "    File \"C:\\Users\\DELL\\AppData\\Roaming\\Python\\Python39\\site-packages\\keras\\src\\engine\\training.py\", line 2413, in run_step  **\n",
      "        outputs = model.predict_step(data)\n",
      "    File \"C:\\Users\\DELL\\AppData\\Roaming\\Python\\Python39\\site-packages\\keras\\src\\engine\\training.py\", line 2381, in predict_step\n",
      "        return self(x, training=False)\n",
      "    File \"C:\\Users\\DELL\\AppData\\Roaming\\Python\\Python39\\site-packages\\keras\\src\\utils\\traceback_utils.py\", line 70, in error_handler\n",
      "        raise e.with_traceback(filtered_tb) from None\n",
      "    File \"C:\\Users\\DELL\\AppData\\Roaming\\Python\\Python39\\site-packages\\keras\\src\\engine\\input_spec.py\", line 219, in assert_input_compatibility\n",
      "        raise ValueError(\n",
      "\n",
      "    ValueError: Layer \"model_2\" expects 2 input(s), but it received 1 input tensors. Inputs received: [<tf.Tensor 'IteratorGetNext:0' shape=(None, 48, 48, 3) dtype=float32>]\n",
      "\n",
      "ani wkeft\n",
      "Error during prediction: in user code:\n",
      "\n",
      "    File \"C:\\Users\\DELL\\AppData\\Roaming\\Python\\Python39\\site-packages\\keras\\src\\engine\\training.py\", line 2440, in predict_function  *\n",
      "        return step_function(self, iterator)\n",
      "    File \"C:\\Users\\DELL\\AppData\\Roaming\\Python\\Python39\\site-packages\\keras\\src\\engine\\training.py\", line 2425, in step_function  **\n",
      "        outputs = model.distribute_strategy.run(run_step, args=(data,))\n",
      "    File \"C:\\Users\\DELL\\AppData\\Roaming\\Python\\Python39\\site-packages\\keras\\src\\engine\\training.py\", line 2413, in run_step  **\n",
      "        outputs = model.predict_step(data)\n",
      "    File \"C:\\Users\\DELL\\AppData\\Roaming\\Python\\Python39\\site-packages\\keras\\src\\engine\\training.py\", line 2381, in predict_step\n",
      "        return self(x, training=False)\n",
      "    File \"C:\\Users\\DELL\\AppData\\Roaming\\Python\\Python39\\site-packages\\keras\\src\\utils\\traceback_utils.py\", line 70, in error_handler\n",
      "        raise e.with_traceback(filtered_tb) from None\n",
      "    File \"C:\\Users\\DELL\\AppData\\Roaming\\Python\\Python39\\site-packages\\keras\\src\\engine\\input_spec.py\", line 219, in assert_input_compatibility\n",
      "        raise ValueError(\n",
      "\n",
      "    ValueError: Layer \"model_2\" expects 2 input(s), but it received 1 input tensors. Inputs received: [<tf.Tensor 'IteratorGetNext:0' shape=(None, 48, 48, 3) dtype=float32>]\n",
      "\n",
      "ani wkeft\n",
      "Error during prediction: in user code:\n",
      "\n",
      "    File \"C:\\Users\\DELL\\AppData\\Roaming\\Python\\Python39\\site-packages\\keras\\src\\engine\\training.py\", line 2440, in predict_function  *\n",
      "        return step_function(self, iterator)\n",
      "    File \"C:\\Users\\DELL\\AppData\\Roaming\\Python\\Python39\\site-packages\\keras\\src\\engine\\training.py\", line 2425, in step_function  **\n",
      "        outputs = model.distribute_strategy.run(run_step, args=(data,))\n",
      "    File \"C:\\Users\\DELL\\AppData\\Roaming\\Python\\Python39\\site-packages\\keras\\src\\engine\\training.py\", line 2413, in run_step  **\n",
      "        outputs = model.predict_step(data)\n",
      "    File \"C:\\Users\\DELL\\AppData\\Roaming\\Python\\Python39\\site-packages\\keras\\src\\engine\\training.py\", line 2381, in predict_step\n",
      "        return self(x, training=False)\n",
      "    File \"C:\\Users\\DELL\\AppData\\Roaming\\Python\\Python39\\site-packages\\keras\\src\\utils\\traceback_utils.py\", line 70, in error_handler\n",
      "        raise e.with_traceback(filtered_tb) from None\n",
      "    File \"C:\\Users\\DELL\\AppData\\Roaming\\Python\\Python39\\site-packages\\keras\\src\\engine\\input_spec.py\", line 219, in assert_input_compatibility\n",
      "        raise ValueError(\n",
      "\n",
      "    ValueError: Layer \"model_2\" expects 2 input(s), but it received 1 input tensors. Inputs received: [<tf.Tensor 'IteratorGetNext:0' shape=(None, 48, 48, 3) dtype=float32>]\n",
      "\n",
      "ani wkeft\n",
      "Error during prediction: in user code:\n",
      "\n",
      "    File \"C:\\Users\\DELL\\AppData\\Roaming\\Python\\Python39\\site-packages\\keras\\src\\engine\\training.py\", line 2440, in predict_function  *\n",
      "        return step_function(self, iterator)\n",
      "    File \"C:\\Users\\DELL\\AppData\\Roaming\\Python\\Python39\\site-packages\\keras\\src\\engine\\training.py\", line 2425, in step_function  **\n",
      "        outputs = model.distribute_strategy.run(run_step, args=(data,))\n",
      "    File \"C:\\Users\\DELL\\AppData\\Roaming\\Python\\Python39\\site-packages\\keras\\src\\engine\\training.py\", line 2413, in run_step  **\n",
      "        outputs = model.predict_step(data)\n",
      "    File \"C:\\Users\\DELL\\AppData\\Roaming\\Python\\Python39\\site-packages\\keras\\src\\engine\\training.py\", line 2381, in predict_step\n",
      "        return self(x, training=False)\n",
      "    File \"C:\\Users\\DELL\\AppData\\Roaming\\Python\\Python39\\site-packages\\keras\\src\\utils\\traceback_utils.py\", line 70, in error_handler\n",
      "        raise e.with_traceback(filtered_tb) from None\n",
      "    File \"C:\\Users\\DELL\\AppData\\Roaming\\Python\\Python39\\site-packages\\keras\\src\\engine\\input_spec.py\", line 219, in assert_input_compatibility\n",
      "        raise ValueError(\n",
      "\n",
      "    ValueError: Layer \"model_2\" expects 2 input(s), but it received 1 input tensors. Inputs received: [<tf.Tensor 'IteratorGetNext:0' shape=(None, 48, 48, 3) dtype=float32>]\n",
      "\n",
      "ani wkeft\n",
      "Error during prediction: in user code:\n",
      "\n",
      "    File \"C:\\Users\\DELL\\AppData\\Roaming\\Python\\Python39\\site-packages\\keras\\src\\engine\\training.py\", line 2440, in predict_function  *\n",
      "        return step_function(self, iterator)\n",
      "    File \"C:\\Users\\DELL\\AppData\\Roaming\\Python\\Python39\\site-packages\\keras\\src\\engine\\training.py\", line 2425, in step_function  **\n",
      "        outputs = model.distribute_strategy.run(run_step, args=(data,))\n",
      "    File \"C:\\Users\\DELL\\AppData\\Roaming\\Python\\Python39\\site-packages\\keras\\src\\engine\\training.py\", line 2413, in run_step  **\n",
      "        outputs = model.predict_step(data)\n",
      "    File \"C:\\Users\\DELL\\AppData\\Roaming\\Python\\Python39\\site-packages\\keras\\src\\engine\\training.py\", line 2381, in predict_step\n",
      "        return self(x, training=False)\n",
      "    File \"C:\\Users\\DELL\\AppData\\Roaming\\Python\\Python39\\site-packages\\keras\\src\\utils\\traceback_utils.py\", line 70, in error_handler\n",
      "        raise e.with_traceback(filtered_tb) from None\n",
      "    File \"C:\\Users\\DELL\\AppData\\Roaming\\Python\\Python39\\site-packages\\keras\\src\\engine\\input_spec.py\", line 219, in assert_input_compatibility\n",
      "        raise ValueError(\n",
      "\n",
      "    ValueError: Layer \"model_2\" expects 2 input(s), but it received 1 input tensors. Inputs received: [<tf.Tensor 'IteratorGetNext:0' shape=(None, 48, 48, 3) dtype=float32>]\n",
      "\n",
      "ani wkeft\n",
      "Error during prediction: in user code:\n",
      "\n",
      "    File \"C:\\Users\\DELL\\AppData\\Roaming\\Python\\Python39\\site-packages\\keras\\src\\engine\\training.py\", line 2440, in predict_function  *\n",
      "        return step_function(self, iterator)\n",
      "    File \"C:\\Users\\DELL\\AppData\\Roaming\\Python\\Python39\\site-packages\\keras\\src\\engine\\training.py\", line 2425, in step_function  **\n",
      "        outputs = model.distribute_strategy.run(run_step, args=(data,))\n",
      "    File \"C:\\Users\\DELL\\AppData\\Roaming\\Python\\Python39\\site-packages\\keras\\src\\engine\\training.py\", line 2413, in run_step  **\n",
      "        outputs = model.predict_step(data)\n",
      "    File \"C:\\Users\\DELL\\AppData\\Roaming\\Python\\Python39\\site-packages\\keras\\src\\engine\\training.py\", line 2381, in predict_step\n",
      "        return self(x, training=False)\n",
      "    File \"C:\\Users\\DELL\\AppData\\Roaming\\Python\\Python39\\site-packages\\keras\\src\\utils\\traceback_utils.py\", line 70, in error_handler\n",
      "        raise e.with_traceback(filtered_tb) from None\n",
      "    File \"C:\\Users\\DELL\\AppData\\Roaming\\Python\\Python39\\site-packages\\keras\\src\\engine\\input_spec.py\", line 219, in assert_input_compatibility\n",
      "        raise ValueError(\n",
      "\n",
      "    ValueError: Layer \"model_2\" expects 2 input(s), but it received 1 input tensors. Inputs received: [<tf.Tensor 'IteratorGetNext:0' shape=(None, 48, 48, 3) dtype=float32>]\n",
      "\n",
      "ani wkeft\n",
      "Error during prediction: in user code:\n",
      "\n",
      "    File \"C:\\Users\\DELL\\AppData\\Roaming\\Python\\Python39\\site-packages\\keras\\src\\engine\\training.py\", line 2440, in predict_function  *\n",
      "        return step_function(self, iterator)\n",
      "    File \"C:\\Users\\DELL\\AppData\\Roaming\\Python\\Python39\\site-packages\\keras\\src\\engine\\training.py\", line 2425, in step_function  **\n",
      "        outputs = model.distribute_strategy.run(run_step, args=(data,))\n",
      "    File \"C:\\Users\\DELL\\AppData\\Roaming\\Python\\Python39\\site-packages\\keras\\src\\engine\\training.py\", line 2413, in run_step  **\n",
      "        outputs = model.predict_step(data)\n",
      "    File \"C:\\Users\\DELL\\AppData\\Roaming\\Python\\Python39\\site-packages\\keras\\src\\engine\\training.py\", line 2381, in predict_step\n",
      "        return self(x, training=False)\n",
      "    File \"C:\\Users\\DELL\\AppData\\Roaming\\Python\\Python39\\site-packages\\keras\\src\\utils\\traceback_utils.py\", line 70, in error_handler\n",
      "        raise e.with_traceback(filtered_tb) from None\n",
      "    File \"C:\\Users\\DELL\\AppData\\Roaming\\Python\\Python39\\site-packages\\keras\\src\\engine\\input_spec.py\", line 219, in assert_input_compatibility\n",
      "        raise ValueError(\n",
      "\n",
      "    ValueError: Layer \"model_2\" expects 2 input(s), but it received 1 input tensors. Inputs received: [<tf.Tensor 'IteratorGetNext:0' shape=(None, 48, 48, 3) dtype=float32>]\n",
      "\n"
     ]
    },
    {
     "ename": "KeyboardInterrupt",
     "evalue": "",
     "output_type": "error",
     "traceback": [
      "\u001b[1;31m---------------------------------------------------------------------------\u001b[0m",
      "\u001b[1;31mKeyboardInterrupt\u001b[0m                         Traceback (most recent call last)",
      "Cell \u001b[1;32mIn[7], line 1\u001b[0m\n\u001b[1;32m----> 1\u001b[0m titi\u001b[38;5;241m=\u001b[39m\u001b[43mprocess_video\u001b[49m\u001b[43m(\u001b[49m\u001b[38;5;124;43m\"\u001b[39;49m\u001b[38;5;124;43myingyinglu.mp4\u001b[39;49m\u001b[38;5;124;43m\"\u001b[39;49m\u001b[43m)\u001b[49m\n",
      "Cell \u001b[1;32mIn[5], line 17\u001b[0m, in \u001b[0;36mprocess_video\u001b[1;34m(input_video_path)\u001b[0m\n\u001b[0;32m     15\u001b[0m total_frames \u001b[38;5;241m+\u001b[39m\u001b[38;5;241m=\u001b[39m \u001b[38;5;241m1\u001b[39m\n\u001b[0;32m     16\u001b[0m gray_frame \u001b[38;5;241m=\u001b[39m cv2\u001b[38;5;241m.\u001b[39mcvtColor(frame, cv2\u001b[38;5;241m.\u001b[39mCOLOR_BGR2GRAY)\n\u001b[1;32m---> 17\u001b[0m faces \u001b[38;5;241m=\u001b[39m \u001b[43mface_detector\u001b[49m\u001b[38;5;241;43m.\u001b[39;49m\u001b[43mdetectMultiScale\u001b[49m\u001b[43m(\u001b[49m\u001b[43mgray_frame\u001b[49m\u001b[43m,\u001b[49m\u001b[43m \u001b[49m\u001b[43mscaleFactor\u001b[49m\u001b[38;5;241;43m=\u001b[39;49m\u001b[38;5;241;43m1.3\u001b[39;49m\u001b[43m,\u001b[49m\u001b[43m \u001b[49m\u001b[43mminNeighbors\u001b[49m\u001b[38;5;241;43m=\u001b[39;49m\u001b[38;5;241;43m10\u001b[39;49m\u001b[43m)\u001b[49m\n\u001b[0;32m     19\u001b[0m \u001b[38;5;28;01mfor\u001b[39;00m (x, y, w, h) \u001b[38;5;129;01min\u001b[39;00m faces:\n\u001b[0;32m     20\u001b[0m     roi_gray_frame \u001b[38;5;241m=\u001b[39m gray_frame[y:y\u001b[38;5;241m+\u001b[39mh, x:x\u001b[38;5;241m+\u001b[39mw]\n",
      "\u001b[1;31mKeyboardInterrupt\u001b[0m: "
     ]
    }
   ],
   "source": [
    "titi=process_video(\"yingyinglu.mp4\")"
   ]
  },
  {
   "cell_type": "code",
   "execution_count": null,
   "metadata": {},
   "outputs": [],
   "source": []
  }
 ],
 "metadata": {
  "kernelspec": {
   "display_name": "Python 3",
   "language": "python",
   "name": "python3"
  },
  "language_info": {
   "codemirror_mode": {
    "name": "ipython",
    "version": 3
   },
   "file_extension": ".py",
   "mimetype": "text/x-python",
   "name": "python",
   "nbconvert_exporter": "python",
   "pygments_lexer": "ipython3",
   "version": "3.9.6"
  }
 },
 "nbformat": 4,
 "nbformat_minor": 2
}
